Workbook

Sheet Rules
B2: 1v1 Match-Play Rules | E2: Win With | F2: Symbol | G2: Points | I2: Player 1 | J2: Player 2
B3: #1 | C3: 1 Mulligan Per Side, Can be used on any shot except putts | E3: Eagle | F3: 🦅 | G3: 4 | I3: Trent | J3: Trey
B4: #2 | C4: Hole value is determined by RNG ($1-$5), unless otherwise agreed upon | E4: Birdie | F4: 🐥 | G4: 2
B5: #3 | C5: Point Values for Winning a Hole are as it states right | E5: Par | F5: 🚩 | G5: 1
B6: #4 | C6: Albatross or Hole in One is worth 20 Points | E6: Bogey | F6: 🧻 | G6: 1
B7: #5 | C7: Triple Bogey Max Score per Hole | E7: Double | F7: 💩 | G7: 0.5
B11: =J3 -> Trey | C11: Points | D11: =SUMIF('Match Log'!C3:C49,"Trey",'Match Log'!D3:D49) -> 31
C12: Money | D12: =SUMIF('Match Log'!C3:C49,"Trey",'Match Log'!F3:F49) -> 99.5
B13: =I3 -> Trent | C13: Points | D13: =SUMIF('Match Log'!C3:C49,"Trent",'Match Log'!D3:D49) -> 31
C14: Money | D14: =SUMIF('Match Log'!C3:C49,"Trent",'Match Log'!F3:F49) -> 110

Sheet Match Log
A1: Match Log | G1: =Rules!I3&" Stats" -> Trent Stats | Q1: =Rules!J3&" Stats" -> Trey Stats
A2: Course | B2: Date | C2: Winner | D2: Margin | E2: Hole Value | F2: Money Won | G2: Front Nine | H2: Back Nine | I2: Total Score | J2: To Par | K2: Eagles | L2: Birdies | M2: Pars | N2: Bogeys | O2: Doubles | P2: Triples | Q2: Front Nine | R2: Back Nine | S2: Total Score | T2: To Par | U2: Eagles | V2: Birdies | W2: Pars | X2: Bogeys | Y2: Doubles | Z2: Triples
A3: Eagle Creek GC | B3: 46023 | C3: Trey | D3: 3 | E3: 1 | F3: 3 | G3: 42 | H3: 44 | I3: 86 | J3: 13 | K3: 0 | L3: 0 | M3: 6 | N3: 11 | O3: 1 | P3: 0 | Q3: 41 | R3: 43 | S3: 84 | T3: 11 | U3: 0 | V3: 1 | W3: 6 | X3: 10 | Y3: 1 | Z3: 0
A4: Heathrow CC | B4: 46039 | C4: Trent | D4: 2 | E4: 2 | F4: 4 | G4: 44 | H4: 48 | I4: 92 | J4: 21 | K4: 0 | L4: 0 | M4: 4 | N4: 7 | O4: 7 | P4: 0 | Q4: 45 | R4: 54 | S4: 99 | T4: 28 | U4: 0 | V4: 0 | W4: 3 | X4: 5 | Y4: 7 | Z4: 3
A5: Wekiva GC | B5: 46041 | C5: Trent | D5: 3 | E5: 2 | F5: 6 | G5: 50 | H5: 41 | I5: 91 | J5: 19 | K5: 0 | L5: 2 | M5: 3 | N5: 7 | O5: 4 | P5: 2 | Q5: 48 | R5: 45 | S5: 93 | T5: 21 | U5: 0 | V5: 0 | W5: 4 | X5: 8 | Y5: 5 | Z5: 1
A6: Twin Rivers GC | B6: 46053 | C6: Trent | D6: 6 | E6: 3 | F6: 18 | G6: 42 | H6: 42 | I6: 84 | J6: 12 | K6: 0 | L6: 0 | M6: 9 | N6: 6 | O6: 3 | P6: 0 | Q6: 41 | R6: 50 | S6: 91 | T6: 19 | U6: 0 | V6: 0 | W6: 7 | X6: 4 | Y6: 6 | Z6: 1
A7: Wedgefield GC | B7: 46060 | C7: Trey | D7: 1 | E7: 2 | F7: 2 | G7: 43 | H7: 45 | I7: 88 | J7: 16 | K7: 0 | L7: 1 | M7: 5 | N7: 7 | O7: 5 | P7: 0 | Q7: 45 | R7: 46 | S7: 91 | T7: 19 | U7: 0 | V7: 2 | W7: 5 | X7: 4 | Y7: 4 | Z7: 3
A8: Royal St Cloud GC | B8: 46069 | C8: Trey | D8: 1 | E8: 5 | F8: 5 | G8: 47 | H8: 41 | I8: 88 | J8: 16 | K8: 0 | L8: 1 | M8: 5 | N8: 7 | O8: 5 | P8: 0 | Q8: 43 | R8: 45 | S8: 88 | T8: 16 | U8: 0 | V8: 0 | W8: 7 | X8: 6 | Y8: 5 | Z8: 0
A9: Stoneybrook East GC | B9: 46074 | C9: Trey | D9: 2 | E9: 4 | F9: 8 | G9: 44 | H9: 44 | I9: 88 | J9: 16 | K9: 0 | L9: 0 | M9: 5 | N9: 10 | O9: 3 | P9: 0 | Q9: 41 | R9: 46 | S9: 87 | T9: 15 | U9: 0 | V9: 0 | W9: 8 | X9: 7 | Y9: 1 | Z9: 2
A10: Wekiva GC | B10: 46081 | C10: Trey | D10: 3.5 | E10: 2 | F10: 7 | G10: 44 | H10: 45 | I10: 89 | J10: 17 | K10: 0 | L10: 1 | M10: 3 | N10: 10 | O10: 4 | P10: 0 | Q10: 41 | R10: 42 | S10: 83 | T10: 11 | U10: 0 | V10: 2 | W10: 7 | X10: 6 | Y10: 2 | Z10: 1
A11: Stoneybrook East GC | B11: 46085 | C11: Trey | D11: 4 | E11: 2 | F11: 8 | G11: 43 | H11: 41 | I11: 84 | J11: 12 | K11: 0 | L11: 0 | M11: 9 | N11: 6 | O11: 3 | P11: 0 | Q11: 38 | R11: 40 | S11: 78 | T11: 6 | U11: 0 | V11: 0 | W11: 13 | X11: 4 | Y11: 1 | Z11: 0
A12: Clermont National | B12: 46103 | C12: Trent | D12: 2 | E12: 3 | F12: 6 | G12: 40 | H12: 41 | I12: 81 | J12: 10 | K12: 0 | L12: 3 | M12: 5 | N12: 7 | O12: 3 | P12: 0 | Q12: 40 | R12: 41 | S12: 81 | T12: 10 | U12: 0 | V12: 1 | W12: 7 | X12: 9 | Y12: 1 | Z12: 0
A13: Twin Rivers GC | B13: 46109 | C13: Trent | D13: 6 | E13: 4 | F13: 24 | G13: 41 | H13: 50 | I13: 91 | J13: 19 | K13: 0 | L13: 1 | M13: 5 | N13: 6 | O13: 4 | P13: 2 | Q13: 47 | R13: 51 | S13: 98 | T13: 26 | U13: 0 | V13: 0 | W13: 1 | X13: 10 | Y13: 5 | Z13: 2
A14: North Shore GC | B14: 46116 | C14: Trey | D14: 3 | E14: 5 | F14: 15 | G14: 43 | H14: 43 | I14: 86 | J14: 14 | K14: 0 | L14: 0 | M14: 6 | N14: 10 | O14: 2 | P14: 0 | Q14: 39 | R14: 42 | S14: 81 | T14: 9 | U14: 0 | V14: 1 | W14: 9 | X14: 6 | Y14: 2 | Z14: 0
... A22: Rio Pinar GC | B22: 46186 | C22: Trent | D22: 3 | E22: 3 | F22: 9 | G22: 38 | H22: 43 | I22: 81 | J22: 9 | K22: 0 | L22: 0 | M22: 10 | N22: 7 | O22: 1 | P22: 0 | Q22: 39 | R22: 48 | S22: 87 | T22: 15 | U22: 0 | V22: 1 | W22: 6 | X22: 7 | Y22: 3 | Z22: 1

Sheet Stats
B2: Year Long Stats | I2: Year Long Standings | L2: Avg | M2: Front 9 | N2: Back 9 | O2: 18 Holes
C3: =Rules!I3 -> Trent | F3: =Rules!J3 -> Trey | I3: Point Leader | J3: =IFS(Rules!D13>Rules!D11,Rules!B13,Rules!D11>Rules!D13,Rules!B11,Rules!D14=Rules!D12,"AS") -> #N/A | L3: =C3 -> Trent | M3: =Average('Match Log'!G3:G49) -> 42.5 | N3: =Average('Match Log'!H3:H49) -> 44.35 | O3: =Average('Match Log'!I3:I49) -> 86.85
B4: Eagles | C4: =SUM('Match Log'!K3:K49) -> 0 | D4: =C4/Stats!$J$8 -> 0 | E4: 🦅 | F4: =SUM('Match Log'!U3:U49) -> 0 | G4: =F4/Stats!$J$8 -> 0 | I4: Margin | J4: =IFS(Rules!D13>Rules!D11,Rules!D13-Rules!D11,Rules!D11>Rules!D13,Rules!D11-Rules!D13) -> #N/A | L4: =F3 -> Trey | M4: =Average('Match Log'!Q3:Q49) -> 42.1 | N4: =Average('Match Log'!R3:R49) -> 44.95 | O4: =Average('Match Log'!S3:S49) -> 87.05
B5: Birdies | C5: =SUM('Match Log'!L3:L49) -> 16 | D5: =C5/Stats!$J$8 -> 0.044444444 | E5: 🐥 | F5: =SUM('Match Log'!V3:V49) -> 15 | G5: =F5/Stats!$J$8 -> 0.041666667 | I5: Money Leader | J5: =IFS(Rules!D14>Rules!D12,Rules!B13,Rules!D12>Rules!D14,Rules!B11,Rules!D14=Rules!D12,"AS") -> Trent
B6: Pars | C6: =SUM('Match Log'!M3:M49) -> 117 | D6: =C6/Stats!$J$8 -> 0.325 | E6: 🚩 | F6: =SUM('Match Log'!W3:W49) -> 130 | G6: =F6/Stats!$J$8 -> 0.36111111 | I6: Money Up | J6: =IFS(Rules!D14>Rules!D12,Rules!D14-Rules!D12,Rules!D12>Rules!D14,Rules!D12-Rules!D14) -> 10.5
B7: Bogeys | C7: =SUM('Match Log'!N3:N49) -> 147 | D7: =C7/Stats!$J$8 -> 0.40833333 | E7: 🧻 | F7: =SUM('Match Log'!X3:X49) -> 132 | G7: =F7/Stats!$J$8 -> 0.36666667
B8: Doubles | C8: =SUM('Match Log'!O3:O49) -> 73 | D8: =C8/Stats!$J$8 -> 0.20277778 | E8: 💩 | F8: =SUM('Match Log'!Y3:Y49) -> 64 | G8: =F8/Stats!$J$8 -> 0.17777778 | I8: Holes Played | J8: =SUM(Stats!C4:C9) -> 360
B9: Triples | C9: =SUM('Match Log'!P3:P49) -> 7 | D9: =C9/Stats!$J$8 -> 0.019444444 | E9: ☠️ | F9: =SUM('Match Log'!Z3:Z49) -> 19 | G9: =F9/Stats!$J$8 -> 0.052777778 | I9: Matches Played | J9: =J8/18 -> 20

Sheet Empty Scorecard Template
B2: (Insert Course Name) | C2: SCORECARD | AB2: Match Stats
B3: (Date Played) | C3: 1 | D3: 2 | E3: 3 | F3: 4 | G3: 5 | H3: 6 | I3: 7 | J3: 8 | K3: 9 | L3: Front 9 | M3: 10 | N3: 11 | O3: 12 | P3: 13 | Q3: 14 | R3: 15 | S3: 16 | T3: 17 | U3: 18 | V3: Back 9 | W3: PAR | Z3: To Par | AC3: =Rules!I3 -> Trent | AD3: (Insert Hole Value) | AE3: =Rules!J3 -> Trey
B4: Par | L4: =SUM(C4:K4) -> 0 | V4: =SUM(M4:U4) -> 0 | W4: =SUM(L4+V4) -> 0 | AB4: Eagles | AC4: =COUNTIF($C$6:$U$6,"🦅") -> 0 | AD4: 🦅 | AE4: =COUNTIF($C$8:$U$8,"🦅") -> 0
B5: =AC3 -> Trent | L5: =SUM(C5:K5) -> 0 | V5: =SUM(M5:U5) -> 0 | W5: =SUM(L5+V5) -> 0 | X5: =IFS(W5>$W$4,"+",$W$4>W5,"") -> #N/A | Y5: =W5-$W$4 -> 0 | Z5: =X5&Y5 -> #N/A | AB5: Birdies | AC5: =COUNTIF($C$6:$U$6,"🐥") -> 0 | AD5: 🐥 | AE5: =COUNTIF($C$8:$U$8,"🐥") -> 0
C6: =IFS(C$4-C5=1,$AD$5,C$4-C5=2,$AD$4,C$4=C5,$AD$6,C$4-C5=-1,$AD$7,C$4-C5=-2,$AD$8,C$4-C5=-3,$AD$9) -> 🚩 | D6: =IFS(D$4-D5=1,$AD$5,D$4-D5=2,$AD$4,D$4=D5,$AD$6,D$4-D5=-1,$AD$7,D$4-D5=-2,$AD$8,D$4-D5=-3,$AD$9) -> 🚩 | E6: =IFS(E$4-E5=1,$AD$5,E$4-E5=2,$AD$4,E$4=E5,$AD$6,E$4-E5=-1,$AD$7,E$4-E5=-2,$AD$8,E$4-E5=-3,$AD$9) -> 🚩 | F6: =IFS(F$4-F5=1,$AD$5,F$4-F5=2,$AD$4,F$4=F5,$AD$6,F$4-F5=-1,$AD$7,F$4-F5=-2,$AD$8,F$4-F5=-3,$AD$9) -> 🚩 | G6: =IFS(G$4-G5=1,$AD$5,G$4-G5=2,$AD$4,G$4=G5,$AD$6,G$4-G5=-1,$AD$7,G$4-G5=-2,$AD$8,G$4-G5=-3,$AD$9) -> 🚩 | H6: =IFS(H$4-H5=1,$AD$5,H$4-H5=2,$AD$4,H$4=H5,$AD$6,H$4-H5=-1,$AD$7,H$4-H5=-2,$AD$8,H$4-H5=-3,$AD$9) -> 🚩 | I6: =IFS(I$4-I5=1,$AD$5,I$4-I5=2,$AD$4,I$4=I5,$AD$6,I$4-I5=-1,$AD$7,I$4-I5=-2,$AD$8,I$4-I5=-3,$AD$9) -> 🚩 | J6: =IFS(J$4-J5=1,$AD$5,J$4-J5=2,$AD$4,J$4=J5,$AD$6,J$4-J5=-1,$AD$7,J$4-J5=-2,$AD$8,J$4-J5=-3,$AD$9) -> 🚩 | K6: =IFS(K$4-K5=1,$AD$5,K$4-K5=2,$AD$4,K$4=K5,$AD$6,K$4-K5=-1,$AD$7,K$4-K5=-2,$AD$8,K$4-K5=-3,$AD$9) -> 🚩 | M6: =IFS(M$4-M5=1,$AD$5,M$4-M5=2,$AD$4,M$4=M5,$AD$6,M$4-M5=-1,$AD$7,M$4-M5=-2,$AD$8,M$4-M5=-3,$AD$9) -> 🚩 | N6: =IFS(N$4-N5=1,$AD$5,N$4-N5=2,$AD$4,N$4=N5,$AD$6,N$4-N5=-1,$AD$7,N$4-N5=-2,$AD$8,N$4-N5=-3,$AD$9) -> 🚩 | O6: =IFS(O$4-O5=1,$AD$5,O$4-O5=2,$AD$4,O$4=O5,$AD$6,O$4-O5=-1,$AD$7,O$4-O5=-2,$AD$8,O$4-O5=-3,$AD$9) -> 🚩 | P6: =IFS(P$4-P5=1,$AD$5,P$4-P5=2,$AD$4,P$4=P5,$AD$6,P$4-P5=-1,$AD$7,P$4-P5=-2,$AD$8,P$4-P5=-3,$AD$9) -> 🚩 | Q6: =IFS(Q$4-Q5=1,$AD$5,Q$4-Q5=2,$AD$4,Q$4=Q5,$AD$6,Q$4-Q5=-1,$AD$7,Q$4-Q5=-2,$AD$8,Q$4-Q5=-3,$AD$9) -> 🚩 | R6: =IFS(R$4-R5=1,$AD$5,R$4-R5=2,$AD$4,R$4=R5,$AD$6,R$4-R5=-1,$AD$7,R$4-R5=-2,$AD$8,R$4-R5=-3,$AD$9) -> 🚩 | S6: =IFS(S$4-S5=1,$AD$5,S$4-S5=2,$AD$4,S$4=S5,$AD$6,S$4-S5=-1,$AD$7,S$4-S5=-2,$AD$8,S$4-S5=-3,$AD$9) -> 🚩 | T6: =IFS(T$4-T5=1,$AD$5,T$4-T5=2,$AD$4,T$4=T5,$AD$6,T$4-T5=-1,$AD$7,T$4-T5=-2,$AD$8,T$4-T5=-3,$AD$9) -> 🚩 | U6: =IFS(U$4-U5=1,$AD$5,U$4-U5=2,$AD$4,U$4=U5,$AD$6,U$4-U5=-1,$AD$7,U$4-U5=-2,$AD$8,U$4-U5=-3,$AD$9) -> 🚩 | AB6: Pars | AC6: =COUNTIF($C$6:$U$6,"🚩") -> 18 | AD6: 🚩 | AE6: =COUNTIF($C$8:$U$8,"🚩") -> 18
B7: =AE3 -> Trey | L7: =SUM(C7:K7) -> 0 | V7: =SUM(M7:U7) -> 0 | W7: =SUM(L7+V7) -> 0 | X7: =IFS(W7>$W$4,"+",$W$4>W7,"") -> #N/A | Y7: =W7-$W$4 -> 0 | Z7: =X7&Y7 -> #N/A | AB7: Bogeys | AC7: =COUNTIF($C$6:$U$6,"🧻") -> 0 | AD7: 🧻 | AE7: =COUNTIF($C$8:$U$8,"🧻") -> 0
C8: =IFS(C$4-C7=1,$AD$5,C$4-C7=2,$AD$4,C$4=C7,$AD$6,C$4-C7=-1,$AD$7,C$4-C7=-2,$AD$8,C$4-C7=-3,$AD$9) -> 🚩 | D8: =IFS(D$4-D7=1,$AD$5,D$4-D7=2,$AD$4,D$4=D7,$AD$6,D$4-D7=-1,$AD$7,D$4-D7=-2,$AD$8,D$4-D7=-3,$AD$9) -> 🚩 | E8: =IFS(E$4-E7=1,$AD$5,E$4-E7=2,$AD$4,E$4=E7,$AD$6,E$4-E7=-1,$AD$7,E$4-E7=-2,$AD$8,E$4-E7=-3,$AD$9) -> 🚩 | F8: =IFS(F$4-F7=1,$AD$5,F$4-F7=2,$AD$4,F$4=F7,$AD$6,F$4-F7=-1,$AD$7,F$4-F7=-2,$AD$8,F$4-F7=-3,$AD$9) -> 🚩 | G8: =IFS(G$4-G7=1,$AD$5,G$4-G7=2,$AD$4,G$4=G7,$AD$6,G$4-G7=-1,$AD$7,G$4-G7=-2,$AD$8,G$4-G7=-3,$AD$9) -> 🚩 | H8: =IFS(H$4-H7=1,$AD$5,H$4-H7=2,$AD$4,H$4=H7,$AD$6,H$4-H7=-1,$AD$7,H$4-H7=-2,$AD$8,H$4-H7=-3,$AD$9) -> 🚩 | I8: =IFS(I$4-I7=1,$AD$5,I$4-I7=2,$AD$4,I$4=I7,$AD$6,I$4-I7=-1,$AD$7,I$4-I7=-2,$AD$8,I$4-I7=-3,$AD$9) -> 🚩 | J8: =IFS(J$4-J7=1,$AD$5,J$4-J7=2,$AD$4,J$4=J7,$AD$6,J$4-J7=-1,$AD$7,J$4-J7=-2,$AD$8,J$4-J7=-3,$AD$9) -> 🚩 | K8: =IFS(K$4-K7=1,$AD$5,K$4-K7=2,$AD$4,K$4=K7,$AD$6,K$4-K7=-1,$AD$7,K$4-K7=-2,$AD$8,K$4-K7=-3,$AD$9) -> 🚩 | M8: =IFS(M$4-M7=1,$AD$5,M$4-M7=2,$AD$4,M$4=M7,$AD$6,M$4-M7=-1,$AD$7,M$4-M7=-2,$AD$8,M$4-M7=-3,$AD$9) -> 🚩 | N8: =IFS(N$4-N7=1,$AD$5,N$4-N7=2,$AD$4,N$4=N7,$AD$6,N$4-N7=-1,$AD$7,N$4-N7=-2,$AD$8,N$4-N7=-3,$AD$9) -> 🚩 | O8: =IFS(O$4-O7=1,$AD$5,O$4-O7=2,$AD$4,O$4=O7,$AD$6,O$4-O7=-1,$AD$7,O$4-O7=-2,$AD$8,O$4-O7=-3,$AD$9) -> 🚩 | P8: =IFS(P$4-P7=1,$AD$5,P$4-P7=2,$AD$4,P$4=P7,$AD$6,P$4-P7=-1,$AD$7,P$4-P7=-2,$AD$8,P$4-P7=-3,$AD$9) -> 🚩 | Q8: =IFS(Q$4-Q7=1,$AD$5,Q$4-Q7=2,$AD$4,Q$4=Q7,$AD$6,Q$4-Q7=-1,$AD$7,Q$4-Q7=-2,$AD$8,Q$4-Q7=-3,$AD$9) -> 🚩 | R8: =IFS(R$4-R7=1,$AD$5,R$4-R7=2,$AD$4,R$4=R7,$AD$6,R$4-R7=-1,$AD$7,R$4-R7=-2,$AD$8,R$4-R7=-3,$AD$9) -> 🚩 | S8: =IFS(S$4-S7=1,$AD$5,S$4-S7=2,$AD$4,S$4=S7,$AD$6,S$4-S7=-1,$AD$7,S$4-S7=-2,$AD$8,S$4-S7=-3,$AD$9) -> 🚩 | T8: =IFS(T$4-T7=1,$AD$5,T$4-T7=2,$AD$4,T$4=T7,$AD$6,T$4-T7=-1,$AD$7,T$4-T7=-2,$AD$8,T$4-T7=-3,$AD$9) -> 🚩 | U8: =IFS(U$4-U7=1,$AD$5,U$4-U7=2,$AD$4,U$4=U7,$AD$6,U$4-U7=-1,$AD$7,U$4-U7=-2,$AD$8,U$4-U7=-3,$AD$9) -> 🚩 | AB8: Doubles | AC8: =COUNTIF($C$6:$U$6,"💩") -> 0 | AD8: 💩 | AE8: =COUNTIF($C$8:$U$8,"💩") -> 0
AB9: Triples | AC9: =COUNTIF($C$6:$U$6,"☠️") -> 0 | AD9: ☠️ | AE9: =COUNTIF($C$8:$U$8,"☠️") -> 0
AB10: Holes Won | AC10: =Count(C22:U22) -> 0 | AE10: =Count(C23:U23) -> 0
AB11: Points Won | AC11: =U24 -> 0 | AE11: =U25 -> 0
AB12: Result | AC12: =IFS(AC11>AE11,AC3,AE11>AC11,AE3,AC11=AE11,"AS") -> AS | AD12: =IFS(AC11>AE11,AC11-AE11,AE11>AC11,AE11-AC11,AC11=AE11,"AS") -> AS | AE12: =AD12*AD3 -> #VALUE!
B18: Running Match Score | C18: =IFS(C24>C25,C24-C25,C25>C24,C25-C24,C24=C25,"AS") -> AS | D18: =IFS(D24>D25,D24-D25,D25>D24,D25-D24,D24=D25,"AS") -> AS | E18: =IFS(E24>E25,E24-E25,E25>E24,E25-E24,E24=E25,"AS") -> AS | F18: =IFS(F24>F25,F24-F25,F25>F24,F25-F24,F24=F25,"AS") -> AS | G18: =IFS(G24>G25,G24-G25,G25>G24,G25-G24,G24=G25,"AS") -> AS | H18: =IFS(H24>H25,H24-H25,H25>H24,H25-H24,H24=H25,"AS") -> AS | I18: =IFS(I24>I25,I24-I25,I25>I24,I25-I24,I24=I25,"AS") -> AS | J18: =IFS(J24>J25,J24-J25,J25>J24,J25-J24,J24=J25,"AS") -> AS | ... U18: =IFS(U24>U25,U24-U25,U25>U24,U25-U24,U24=U25,"AS") -> AS
B19: =AC3 -> Trent | C19: =IF(C$5<C$7,C6,) | D19: =IF(D5<D7,D6,) | E19: =IF(E5<E7,E6,) | F19: =IF(F5<F7,F6,) | G19: =IF(G5<G7,G6,) | H19: =IF(H5<H7,H6,) | I19: =IF(I5<I7,I6,) | J19: =IF(J5<J7,J6,) | K19: =IF(K5<K7,K6,) | M19: =IF(M5<M7,M6,) | N19: =IF(N5<N7,N6,) | O19: =IF(O5<O7,O6,) | P19: =IF(P5<P7,P6,) | Q19: =IF(Q5<Q7,Q6,) | R19: =IF(R5<R7,R6,) | S19: =IF(S5<S7,S6,) | T19: =IF(T5<T7,T6,) | U19: =IF(U5<U7,U6,)
B20: =AE3 -> Trey | C20: =IF(C$5>C$7,C8,) | D20: =IF(D$5>D$7,D8,) | E20: =IF(E$5>E$7,E8,) | F20: =IF(F$5>F$7,F8,) | G20: =IF(G$5>G$7,G8,) | H20: =IF(H$5>H$7,H8,) | I20: =IF(I$5>I$7,I8,) | J20: =IF(J$5>J$7,J8,) | K20: =IF(K$5>K$7,K8,) | M20: =IF(M$5>M$7,M8,) | N20: =IF(N$5>N$7,N8,) | O20: =IF(O$5>O$7,O8,) | P20: =IF(P$5>P$7,P8,) | Q20: =IF(Q$5>Q$7,Q8,) | R20: =IF(R$5>R$7,R8,) | S20: =IF(S$5>S$7,S8,) | T20: =IF(T$5>T$7,T8,) | U20: =IF(U$5>U$7,U8,)
B21: Match Points Awarded
B22: =AC3 -> Trent | C22: =IFS(C19=$AD$4,Rules!$G$3,C19=$AD$5,Rules!$G$4,C19=$AD$6,Rules!$G$5,C19=$AD$7,Rules!$G$6,C19=$AD$8,Rules!$G$7,C19="",) | D22: =IFS(D19=$AD$4,Rules!$G$3,D19=$AD$5,Rules!$G$4,D19=$AD$6,Rules!$G$5,D19=$AD$7,Rules!$G$6,D19=$AD$8,Rules!$G$7,D19="",) | E22: =IFS(E19=$AD$4,Rules!$G$3,E19=$AD$5,Rules!$G$4,E19=$AD$6,Rules!$G$5,E19=$AD$7,Rules!$G$6,E19=$AD$8,Rules!$G$7,E19="",) | F22: =IFS(F19=$AD$4,Rules!$G$3,F19=$AD$5,Rules!$G$4,F19=$AD$6,Rules!$G$5,F19=$AD$7,Rules!$G$6,F19=$AD$8,Rules!$G$7,F19="",) | G22: =IFS(G19=$AD$4,Rules!$G$3,G19=$AD$5,Rules!$G$4,G19=$AD$6,Rules!$G$5,G19=$AD$7,Rules!$G$6,G19=$AD$8,Rules!$G$7,G19="",) | H22: =IFS(H19=$AD$4,Rules!$G$3,H19=$AD$5,Rules!$G$4,H19=$AD$6,Rules!$G$5,H19=$AD$7,Rules!$G$6,H19=$AD$8,Rules!$G$7,H19="",) | I22: =IFS(I19=$AD$4,Rules!$G$3,I19=$AD$5,Rules!$G$4,I19=$AD$6,Rules!$G$5,I19=$AD$7,Rules!$G$6,I19=$AD$8,Rules!$G$7,I19="",) | J22: =IFS(J19=$AD$4,Rules!$G$3,J19=$AD$5,Rules!$G$4,J19=$AD$6,Rules!$G$5,J19=$AD$7,Rules!$G$6,J19=$AD$8,Rules!$G$7,J19="",) | K22: =IFS(K19=$AD$4,Rules!$G$3,K19=$AD$5,Rules!$G$4,K19=$AD$6,Rules!$G$5,K19=$AD$7,Rules!$G$6,K19=$AD$8,Rules!$G$7,K19="",) | M22: =IFS(M19=$AD$4,Rules!$G$3,M19=$AD$5,Rules!$G$4,M19=$AD$6,Rules!$G$5,M19=$AD$7,Rules!$G$6,M19=$AD$8,Rules!$G$7,M19="",) | N22: =IFS(N19=$AD$4,Rules!$G$3,N19=$AD$5,Rules!$G$4,N19=$AD$6,Rules!$G$5,N19=$AD$7,Rules!$G$6,N19=$AD$8,Rules!$G$7,N19="",) | O22: =IFS(O19=$AD$4,Rules!$G$3,O19=$AD$5,Rules!$G$4,O19=$AD$6,Rules!$G$5,O19=$AD$7,Rules!$G$6,O19=$AD$8,Rules!$G$7,O19="",) | P22: =IFS(P19=$AD$4,Rules!$G$3,P19=$AD$5,Rules!$G$4,P19=$AD$6,Rules!$G$5,P19=$AD$7,Rules!$G$6,P19=$AD$8,Rules!$G$7,P19="",) | Q22: =IFS(Q19=$AD$4,Rules!$G$3,Q19=$AD$5,Rules!$G$4,Q19=$AD$6,Rules!$G$5,Q19=$AD$7,Rules!$G$6,Q19=$AD$8,Rules!$G$7,Q19="",) | R22: =IFS(R19=$AD$4,Rules!$G$3,R19=$AD$5,Rules!$G$4,R19=$AD$6,Rules!$G$5,R19=$AD$7,Rules!$G$6,R19=$AD$8,Rules!$G$7,R19="",) | S22: =IFS(S19=$AD$4,Rules!$G$3,S19=$AD$5,Rules!$G$4,S19=$AD$6,Rules!$G$5,S19=$AD$7,Rules!$G$6,S19=$AD$8,Rules!$G$7,S19="",) | T22: =IFS(T19=$AD$4,Rules!$G$3,T19=$AD$5,Rules!$G$4,T19=$AD$6,Rules!$G$5,T19=$AD$7,Rules!$G$6,T19=$AD$8,Rules!$G$7,T19="",) | U22: =IFS(U19=$AD$4,Rules!$G$3,U19=$AD$5,Rules!$G$4,U19=$AD$6,Rules!$G$5,U19=$AD$7,Rules!$G$6,U19=$AD$8,Rules!$G$7,U19="",)
B23: =AE3 -> Trey | C23: =IFS(C20=$AD$4,Rules!$G$3,C20=$AD$5,Rules!$G$4,C20=$AD$6,Rules!$G$5,C20=$AD$7,Rules!$G$6,C20=$AD$8,Rules!$G$7,C20="",) | D23: =IFS(D20=$AD$4,Rules!$G$3,D20=$AD$5,Rules!$G$4,D20=$AD$6,Rules!$G$5,D20=$AD$7,Rules!$G$6,D20=$AD$8,Rules!$G$7,D20="",) | E23: =IFS(E20=$AD$4,Rules!$G$3,E20=$AD$5,Rules!$G$4,E20=$AD$6,Rules!$G$5,E20=$AD$7,Rules!$G$6,E20=$AD$8,Rules!$G$7,E20="",) | F23: =IFS(F20=$AD$4,Rules!$G$3,F20=$AD$5,Rules!$G$4,F20=$AD$6,Rules!$G$5,F20=$AD$7,Rules!$G$6,F20=$AD$8,Rules!$G$7,F20="",) | G23: =IFS(G20=$AD$4,Rules!$G$3,G20=$AD$5,Rules!$G$4,G20=$AD$6,Rules!$G$5,G20=$AD$7,Rules!$G$6,G20=$AD$8,Rules!$G$7,G20="",) | H23: =IFS(H20=$AD$4,Rules!$G$3,H20=$AD$5,Rules!$G$4,H20=$AD$6,Rules!$G$5,H20=$AD$7,Rules!$G$6,H20=$AD$8,Rules!$G$7,H20="",) | I23: =IFS(I20=$AD$4,Rules!$G$3,I20=$AD$5,Rules!$G$4,I20=$AD$6,Rules!$G$5,I20=$AD$7,Rules!$G$6,I20=$AD$8,Rules!$G$7,I20="",) | J23: =IFS(J20=$AD$4,Rules!$G$3,J20=$AD$5,Rules!$G$4,J20=$AD$6,Rules!$G$5,J20=$AD$7,Rules!$G$6,J20=$AD$8,Rules!$G$7,J20="",) | K23: =IFS(K20=$AD$4,Rules!$G$3,K20=$AD$5,Rules!$G$4,K20=$AD$6,Rules!$G$5,K20=$AD$7,Rules!$G$6,K20=$AD$8,Rules!$G$7,K20="",) | M23: =IFS(M20=$AD$4,Rules!$G$3,M20=$AD$5,Rules!$G$4,M20=$AD$6,Rules!$G$5,M20=$AD$7,Rules!$G$6,M20=$AD$8,Rules!$G$7,M20="",) | N23: =IFS(N20=$AD$4,Rules!$G$3,N20=$AD$5,Rules!$G$4,N20=$AD$6,Rules!$G$5,N20=$AD$7,Rules!$G$6,N20=$AD$8,Rules!$G$7,N20="",) | O23: =IFS(O20=$AD$4,Rules!$G$3,O20=$AD$5,Rules!$G$4,O20=$AD$6,Rules!$G$5,O20=$AD$7,Rules!$G$6,O20=$AD$8,Rules!$G$7,O20="",) | P23: =IFS(P20=$AD$4,Rules!$G$3,P20=$AD$5,Rules!$G$4,P20=$AD$6,Rules!$G$5,P20=$AD$7,Rules!$G$6,P20=$AD$8,Rules!$G$7,P20="",) | Q23: =IFS(Q20=$AD$4,Rules!$G$3,Q20=$AD$5,Rules!$G$4,Q20=$AD$6,Rules!$G$5,Q20=$AD$7,Rules!$G$6,Q20=$AD$8,Rules!$G$7,Q20="",) | R23: =IFS(R20=$AD$4,Rules!$G$3,R20=$AD$5,Rules!$G$4,R20=$AD$6,Rules!$G$5,R20=$AD$7,Rules!$G$6,R20=$AD$8,Rules!$G$7,R20="",) | S23: =IFS(S20=$AD$4,Rules!$G$3,S20=$AD$5,Rules!$G$4,S20=$AD$6,Rules!$G$5,S20=$AD$7,Rules!$G$6,S20=$AD$8,Rules!$G$7,S20="",) | T23: =IFS(T20=$AD$4,Rules!$G$3,T20=$AD$5,Rules!$G$4,T20=$AD$6,Rules!$G$5,T20=$AD$7,Rules!$G$6,T20=$AD$8,Rules!$G$7,T20="",) | U23: =IFS(U20=$AD$4,Rules!$G$3,U20=$AD$5,Rules!$G$4,U20=$AD$6,Rules!$G$5,U20=$AD$7,Rules!$G$6,U20=$AD$8,Rules!$G$7,U20="",)
B24: Trent Running Points Won | C24: =C22 | D24: =D22+C24 -> 0 | E24: =E22+D24 -> 0 | F24: =F22+E24 -> 0 | G24: =G22+F24 -> 0 | H24: =H22+G24 -> 0 | I24: =I22+H24 -> 0 | J24: =J22+I24 -> 0 | K24: =K22+J24 -> 0 | ... U24: =U22+T24 -> 0
B25: Trey Running Points Won | C25: =C23 | D25: =D23+C25 -> 0 | E25: =E23+D25 -> 0 | F25: =F23+E25 -> 0 | G25: =G23+F25 -> 0 | H25: =H23+G25 -> 0 | I25: =I23+H25 -> 0 | J25: =J23+I25 -> 0 | K25: =K23+J25 -> 0 | ... U25: =U23+T25 -> 0

Sheet Rio Pinar GC - 2026-06-13
B2: Rio Pinar GC | C2: SCORECARD | AB2: Match Stats
B3: 46186 | C3: 1 | D3: 2 | E3: 3 | F3: 4 | G3: 5 | H3: 6 | I3: 7 | J3: 8 | K3: 9 | L3: Front 9 | M3: 10 | N3: 11 | O3: 12 | P3: 13 | Q3: 14 | R3: 15 | S3: 16 | T3: 17 | U3: 18 | V3: Back 9 | W3: PAR | Z3: To Par | AC3: =Rules!I3 -> Trent | AD3: 3 | AE3: =Rules!J3 -> Trey
B4: Par | C4: 5 | D4: 4 | E4: 3 | F4: 4 | G4: 4 | H4: 5 | I4: 3 | J4: 4 | K4: 4 | L4: =SUM(C4:K4) -> 36 | M4: 5 | N4: 4 | O4: 4 | P4: 3 | Q4: 4 | R4: 4 | S4: 5 | T4: 3 | U4: 4 | V4: =SUM(M4:U4) -> 36 | W4: =SUM(L4+V4) -> 72 | AB4: Eagles | AC4: =COUNTIF($C$6:$U$6,"🦅") -> 0 | AD4: 🦅 | AE4: =COUNTIF($C$8:$U$8,"🦅") -> 0
B5: =AC3 -> Trent | C5: 5 | D5: 4 | E5: 3 | F5: 5 | G5: 4 | H5: 5 | I5: 3 | J5: 4 | K5: 5 | L5: =SUM(C5:K5) -> 38 | M5: 5 | N5: 5 | O5: 5 | P5: 4 | Q5: 4 | R5: 4 | S5: 7 | T5: 4 | U5: 5 | V5: =SUM(M5:U5) -> 43 | W5: =SUM(L5+V5) -> 81 | X5: =IFS(W5>$W$4,"+",$W$4>W5,"") -> + | Y5: =W5-$W$4 -> 9 | Z5: =X5&Y5 -> +9 | AB5: Birdies | AC5: =COUNTIF($C$6:$U$6,"🐥") -> 0 | AD5: 🐥 | AE5: =COUNTIF($C$8:$U$8,"🐥") -> 1
C6: =IFS(C$4-C5=1,$AD$5,C$4-C5=2,$AD$4,C$4=C5,$AD$6,C$4-C5=-1,$AD$7,C$4-C5=-2,$AD$8,C$4-C5=-3,$AD$9) -> 🚩 | D6: =IFS(D$4-D5=1,$AD$5,D$4-D5=2,$AD$4,D$4=D5,$AD$6,D$4-D5=-1,$AD$7,D$4-D5=-2,$AD$8,D$4-D5=-3,$AD$9) -> 🚩 | E6: =IFS(E$4-E5=1,$AD$5,E$4-E5=2,$AD$4,E$4=E5,$AD$6,E$4-E5=-1,$AD$7,E$4-E5=-2,$AD$8,E$4-E5=-3,$AD$9) -> 🚩 | F6: =IFS(F$4-F5=1,$AD$5,F$4-F5=2,$AD$4,F$4=F5,$AD$6,F$4-F5=-1,$AD$7,F$4-F5=-2,$AD$8,F$4-F5=-3,$AD$9) -> 🧻 | G6: =IFS(G$4-G5=1,$AD$5,G$4-G5=2,$AD$4,G$4=G5,$AD$6,G$4-G5=-1,$AD$7,G$4-G5=-2,$AD$8,G$4-G5=-3,$AD$9) -> 🚩 | H6: =IFS(H$4-H5=1,$AD$5,H$4-H5=2,$AD$4,H$4=H5,$AD$6,H$4-H5=-1,$AD$7,H$4-H5=-2,$AD$8,H$4-H5=-3,$AD$9) -> 🚩 | I6: =IFS(I$4-I5=1,$AD$5,I$4-I5=2,$AD$4,I$4=I5,$AD$6,I$4-I5=-1,$AD$7,I$4-I5=-2,$AD$8,I$4-I5=-3,$AD$9) -> 🚩 | J6: =IFS(J$4-J5=1,$AD$5,J$4-J5=2,$AD$4,J$4=J5,$AD$6,J$4-J5=-1,$AD$7,J$4-J5=-2,$AD$8,J$4-J5=-3,$AD$9) -> 🚩 | K6: =IFS(K$4-K5=1,$AD$5,K$4-K5=2,$AD$4,K$4=K5,$AD$6,K$4-K5=-1,$AD$7,K$4-K5=-2,$AD$8,K$4-K5=-3,$AD$9) -> 🧻 | M6: =IFS(M$4-M5=1,$AD$5,M$4-M5=2,$AD$4,M$4=M5,$AD$6,M$4-M5=-1,$AD$7,M$4-M5=-2,$AD$8,M$4-M5=-3,$AD$9) -> 🚩 | N6: =IFS(N$4-N5=1,$AD$5,N$4-N5=2,$AD$4,N$4=N5,$AD$6,N$4-N5=-1,$AD$7,N$4-N5=-2,$AD$8,N$4-N5=-3,$AD$9) -> 🧻 | O6: =IFS(O$4-O5=1,$AD$5,O$4-O5=2,$AD$4,O$4=O5,$AD$6,O$4-O5=-1,$AD$7,O$4-O5=-2,$AD$8,O$4-O5=-3,$AD$9) -> 🧻 | P6: =IFS(P$4-P5=1,$AD$5,P$4-P5=2,$AD$4,P$4=P5,$AD$6,P$4-P5=-1,$AD$7,P$4-P5=-2,$AD$8,P$4-P5=-3,$AD$9) -> 🧻 | Q6: =IFS(Q$4-Q5=1,$AD$5,Q$4-Q5=2,$AD$4,Q$4=Q5,$AD$6,Q$4-Q5=-1,$AD$7,Q$4-Q5=-2,$AD$8,Q$4-Q5=-3,$AD$9) -> 🚩 | R6: =IFS(R$4-R5=1,$AD$5,R$4-R5=2,$AD$4,R$4=R5,$AD$6,R$4-R5=-1,$AD$7,R$4-R5=-2,$AD$8,R$4-R5=-3,$AD$9) -> 🚩 | S6: =IFS(S$4-S5=1,$AD$5,S$4-S5=2,$AD$4,S$4=S5,$AD$6,S$4-S5=-1,$AD$7,S$4-S5=-2,$AD$8,S$4-S5=-3,$AD$9) -> 💩 | T6: =IFS(T$4-T5=1,$AD$5,T$4-T5=2,$AD$4,T$4=T5,$AD$6,T$4-T5=-1,$AD$7,T$4-T5=-2,$AD$8,T$4-T5=-3,$AD$9) -> 🧻 | U6: =IFS(U$4-U5=1,$AD$5,U$4-U5=2,$AD$4,U$4=U5,$AD$6,U$4-U5=-1,$AD$7,U$4-U5=-2,$AD$8,U$4-U5=-3,$AD$9) -> 🧻 | AB6: Pars | AC6: =COUNTIF($C$6:$U$6,"🚩") -> 10 | AD6: 🚩 | AE6: =COUNTIF($C$8:$U$8,"🚩") -> 6
B7: =AE3 -> Trey | C7: 6 | D7: 5 | E7: 3 | F7: 4 | G7: 5 | H7: 6 | I7: 2 | J7: 4 | K7: 4 | L7: =SUM(C7:K7) -> 39 | M7: 5 | N7: 5 | O7: 7 | P7: 4 | Q7: 5 | R7: 6 | S7: 7 | T7: 5 | U7: 4 | V7: =SUM(M7:U7) -> 48 | W7: =SUM(L7+V7) -> 87 | X7: =IFS(W7>$W$4,"+",$W$4>W7,"") -> + | Y7: =W7-$W$4 -> 15 | Z7: =X7&Y7 -> +15 | AB7: Bogeys | AC7: =COUNTIF($C$6:$U$6,"🧻") -> 7 | AD7: 🧻 | AE7: =COUNTIF($C$8:$U$8,"🧻") -> 7
C8: =IFS(C$4-C7=1,$AD$5,C$4-C7=2,$AD$4,C$4=C7,$AD$6,C$4-C7=-1,$AD$7,C$4-C7=-2,$AD$8,C$4-C7=-3,$AD$9) -> 🧻 | D8: =IFS(D$4-D7=1,$AD$5,D$4-D7=2,$AD$4,D$4=D7,$AD$6,D$4-D7=-1,$AD$7,D$4-D7=-2,$AD$8,D$4-D7=-3,$AD$9) -> 🧻 | E8: =IFS(E$4-E7=1,$AD$5,E$4-E7=2,$AD$4,E$4=E7,$AD$6,E$4-E7=-1,$AD$7,E$4-E7=-2,$AD$8,E$4-E7=-3,$AD$9) -> 🚩 | F8: =IFS(F$4-F7=1,$AD$5,F$4-F7=2,$AD$4,F$4=F7,$AD$6,F$4-F7=-1,$AD$7,F$4-F7=-2,$AD$8,F$4-F7=-3,$AD$9) -> 🚩 | G8: =IFS(G$4-G7=1,$AD$5,G$4-G7=2,$AD$4,G$4=G7,$AD$6,G$4-G7=-1,$AD$7,G$4-G7=-2,$AD$8,G$4-G7=-3,$AD$9) -> 🧻 | H8: =IFS(H$4-H7=1,$AD$5,H$4-H7=2,$AD$4,H$4=H7,$AD$6,H$4-H7=-1,$AD$7,H$4-H7=-2,$AD$8,H$4-H7=-3,$AD$9) -> 🧻 | I8: =IFS(I$4-I7=1,$AD$5,I$4-I7=2,$AD$4,I$4=I7,$AD$6,I$4-I7=-1,$AD$7,I$4-I7=-2,$AD$8,I$4-I7=-3,$AD$9) -> 🐥 | J8: =IFS(J$4-J7=1,$AD$5,J$4-J7=2,$AD$4,J$4=J7,$AD$6,J$4-J7=-1,$AD$7,J$4-J7=-2,$AD$8,J$4-J7=-3,$AD$9) -> 🚩 | K8: =IFS(K$4-K7=1,$AD$5,K$4-K7=2,$AD$4,K$4=K7,$AD$6,K$4-K7=-1,$AD$7,K$4-K7=-2,$AD$8,K$4-K7=-3,$AD$9) -> 🚩 | M8: =IFS(M$4-M7=1,$AD$5,M$4-M7=2,$AD$4,M$4=M7,$AD$6,M$4-M7=-1,$AD$7,M$4-M7=-2,$AD$8,M$4-M7=-3,$AD$9) -> 🚩 | N8: =IFS(N$4-N7=1,$AD$5,N$4-N7=2,$AD$4,N$4=N7,$AD$6,N$4-N7=-1,$AD$7,N$4-N7=-2,$AD$8,N$4-N7=-3,$AD$9) -> 🧻 | O8: =IFS(O$4-O7=1,$AD$5,O$4-O7=2,$AD$4,O$4=O7,$AD$6,O$4-O7=-1,$AD$7,O$4-O7=-2,$AD$8,O$4-O7=-3,$AD$9) -> ☠️ | P8: =IFS(P$4-P7=1,$AD$5,P$4-P7=2,$AD$4,P$4=P7,$AD$6,P$4-P7=-1,$AD$7,P$4-P7=-2,$AD$8,P$4-P7=-3,$AD$9) -> 🧻 | Q8: =IFS(Q$4-Q7=1,$AD$5,Q$4-Q7=2,$AD$4,Q$4=Q7,$AD$6,Q$4-Q7=-1,$AD$7,Q$4-Q7=-2,$AD$8,Q$4-Q7=-3,$AD$9) -> 🧻 | R8: =IFS(R$4-R7=1,$AD$5,R$4-R7=2,$AD$4,R$4=R7,$AD$6,R$4-R7=-1,$AD$7,R$4-R7=-2,$AD$8,R$4-R7=-3,$AD$9) -> 💩 | S8: =IFS(S$4-S7=1,$AD$5,S$4-S7=2,$AD$4,S$4=S7,$AD$6,S$4-S7=-1,$AD$7,S$4-S7=-2,$AD$8,S$4-S7=-3,$AD$9) -> 💩 | T8: =IFS(T$4-T7=1,$AD$5,T$4-T7=2,$AD$4,T$4=T7,$AD$6,T$4-T7=-1,$AD$7,T$4-T7=-2,$AD$8,T$4-T7=-3,$AD$9) -> 💩 | U8: =IFS(U$4-U7=1,$AD$5,U$4-U7=2,$AD$4,U$4=U7,$AD$6,U$4-U7=-1,$AD$7,U$4-U7=-2,$AD$8,U$4-U7=-3,$AD$9) -> 🚩 | AB8: Doubles | AC8: =COUNTIF($C$6:$U$6,"💩") -> 1 | AD8: 💩 | AE8: =COUNTIF($C$8:$U$8,"💩") -> 3
AB9: Triples | AC9: =COUNTIF($C$6:$U$6,"☠️") -> 0 | AD9: ☠️ | AE9: =COUNTIF($C$8:$U$8,"☠️") -> 1
AB10: Holes Won | AC10: =Count(C22:U22) -> 8 | AE10: =Count(C23:U23) -> 4
AB11: Points Won | AC11: =U24 -> 8 | AE11: =U25 -> 5
AB12: Result | AC12: =IFS(AC11>AE11,AC3,AE11>AC11,AE3,AC11=AE11,"AS") -> Trent | AD12: =IFS(AC11>AE11,AC11-AE11,AE11>AC11,AE11-AC11,AC11=AE11,"AS") -> 3 | AE12: =AD12*AD3 -> 9
B18: Running Match Score | C18: =IFS(C24>C25,C24-C25,C25>C24,C25-C24,C24=C25,"AS") -> 1 | D18: =IFS(D24>D25,D24-D25,D25>D24,D25-D24,D24=D25,"AS") -> 2 | E18: =IFS(E24>E25,E24-E25,E25>E24,E25-E24,E24=E25,"AS") -> 2 | F18: =IFS(F24>F25,F24-F25,F25>F24,F25-F24,F24=F25,"AS") -> 1 | G18: =IFS(G24>G25,G24-G25,G25>G24,G25-G24,G24=G25,"AS") -> 2 | H18: =IFS(H24>H25,H24-H25,H25>H24,H25-H24,H24=H25,"AS") -> 3 | I18: =IFS(I24>I25,I24-I25,I25>I24,I25-I24,I24=I25,"AS") -> 1 | J18: =IFS(J24>J25,J24-J25,J25>J24,J25-J24,J24=J25,"AS") -> 1 | ... U18: =IFS(U24>U25,U24-U25,U25>U24,U25-U24,U24=U25,"AS") -> 3
B19: =AC3 -> Trent | C19: =IF(C$5<C$7,C6,) -> 🚩 | D19: =IF(D5<D7,D6,) -> 🚩 | E19: =IF(E5<E7,E6,) | F19: =IF(F5<F7,F6,) | G19: =IF(G5<G7,G6,) -> 🚩 | H19: =IF(H5<H7,H6,) -> 🚩 | I19: =IF(I5<I7,I6,) | J19: =IF(J5<J7,J6,) | K19: =IF(K5<K7,K6,) | M19: =IF(M5<M7,M6,) | N19: =IF(N5<N7,N6,) | O19: =IF(O5<O7,O6,) -> 🧻 | P19: =IF(P5<P7,P6,) | Q19: =IF(Q5<Q7,Q6,) -> 🚩 | R19: =IF(R5<R7,R6,) -> 🚩 | S19: =IF(S5<S7,S6,) | T19: =IF(T5<T7,T6,) -> 🧻 | U19: =IF(U5<U7,U6,)
B20: =AE3 -> Trey | C20: =IF(C$5>C$7,C8,) | D20: =IF(D$5>D$7,D8,) | E20: =IF(E$5>E$7,E8,) | F20: =IF(F$5>F$7,F8,) -> 🚩 | G20: =IF(G$5>G$7,G8,) | H20: =IF(H$5>H$7,H8,) | I20: =IF(I$5>I$7,I8,) -> 🐥 | J20: =IF(J$5>J$7,J8,) | K20: =IF(K$5>K$7,K8,) -> 🚩 | M20: =IF(M$5>M$7,M8,) | N20: =IF(N$5>N$7,N8,) | O20: =IF(O$5>O$7,O8,) | P20: =IF(P$5>P$7,P8,) | Q20: =IF(Q$5>Q$7,Q8,) | R20: =IF(R$5>R$7,R8,) | S20: =IF(S$5>S$7,S8,) | T20: =IF(T$5>T$7,T8,) | U20: =IF(U$5>U$7,U8,) -> 🚩
B21: Match Points Awarded
B22: =AC3 -> Trent | C22: =IFS(C19=$AD$4,Rules!$G$3,C19=$AD$5,Rules!$G$4,C19=$AD$6,Rules!$G$5,C19=$AD$7,Rules!$G$6,C19=$AD$8,Rules!$G$7,C19="",) -> 1 | D22: =IFS(D19=$AD$4,Rules!$G$3,D19=$AD$5,Rules!$G$4,D19=$AD$6,Rules!$G$5,D19=$AD$7,Rules!$G$6,D19=$AD$8,Rules!$G$7,D19="",) -> 1 | E22: =IFS(E19=$AD$4,Rules!$G$3,E19=$AD$5,Rules!$G$4,E19=$AD$6,Rules!$G$5,E19=$AD$7,Rules!$G$6,E19=$AD$8,Rules!$G$7,E19="",) | F22: =IFS(F19=$AD$4,Rules!$G$3,F19=$AD$5,Rules!$G$4,F19=$AD$6,Rules!$G$5,F19=$AD$7,Rules!$G$6,F19=$AD$8,Rules!$G$7,F19="",) | G22: =IFS(G19=$AD$4,Rules!$G$3,G19=$AD$5,Rules!$G$4,G19=$AD$6,Rules!$G$5,G19=$AD$7,Rules!$G$6,G19=$AD$8,Rules!$G$7,G19="",) -> 1 | H22: =IFS(H19=$AD$4,Rules!$G$3,H19=$AD$5,Rules!$G$4,H19=$AD$6,Rules!$G$5,H19=$AD$7,Rules!$G$6,H19=$AD$8,Rules!$G$7,H19="",) -> 1 | I22: =IFS(I19=$AD$4,Rules!$G$3,I19=$AD$5,Rules!$G$4,I19=$AD$6,Rules!$G$5,I19=$AD$7,Rules!$G$6,I19=$AD$8,Rules!$G$7,I19="",) | J22: =IFS(J19=$AD$4,Rules!$G$3,J19=$AD$5,Rules!$G$4,J19=$AD$6,Rules!$G$5,J19=$AD$7,Rules!$G$6,J19=$AD$8,Rules!$G$7,J19="",) | K22: =IFS(K19=$AD$4,Rules!$G$3,K19=$AD$5,Rules!$G$4,K19=$AD$6,Rules!$G$5,K19=$AD$7,Rules!$G$6,K19=$AD$8,Rules!$G$7,K19="",) | M22: =IFS(M19=$AD$4,Rules!$G$3,M19=$AD$5,Rules!$G$4,M19=$AD$6,Rules!$G$5,M19=$AD$7,Rules!$G$6,M19=$AD$8,Rules!$G$7,M19="",) | N22: =IFS(N19=$AD$4,Rules!$G$3,N19=$AD$5,Rules!$G$4,N19=$AD$6,Rules!$G$5,N19=$AD$7,Rules!$G$6,N19=$AD$8,Rules!$G$7,N19="",) | O22: =IFS(O19=$AD$4,Rules!$G$3,O19=$AD$5,Rules!$G$4,O19=$AD$6,Rules!$G$5,O19=$AD$7,Rules!$G$6,O19=$AD$8,Rules!$G$7,O19="",) -> 1 | P22: =IFS(P19=$AD$4,Rules!$G$3,P19=$AD$5,Rules!$G$4,P19=$AD$6,Rules!$G$5,P19=$AD$7,Rules!$G$6,P19=$AD$8,Rules!$G$7,P19="",) | Q22: =IFS(Q19=$AD$4,Rules!$G$3,Q19=$AD$5,Rules!$G$4,Q19=$AD$6,Rules!$G$5,Q19=$AD$7,Rules!$G$6,Q19=$AD$8,Rules!$G$7,Q19="",) -> 1 | R22: =IFS(R19=$AD$4,Rules!$G$3,R19=$AD$5,Rules!$G$4,R19=$AD$6,Rules!$G$5,R19=$AD$7,Rules!$G$6,R19=$AD$8,Rules!$G$7,R19="",) -> 1 | S22: =IFS(S19=$AD$4,Rules!$G$3,S19=$AD$5,Rules!$G$4,S19=$AD$6,Rules!$G$5,S19=$AD$7,Rules!$G$6,S19=$AD$8,Rules!$G$7,S19="",) | T22: =IFS(T19=$AD$4,Rules!$G$3,T19=$AD$5,Rules!$G$4,T19=$AD$6,Rules!$G$5,T19=$AD$7,Rules!$G$6,T19=$AD$8,Rules!$G$7,T19="",) -> 1 | U22: =IFS(U19=$AD$4,Rules!$G$3,U19=$AD$5,Rules!$G$4,U19=$AD$6,Rules!$G$5,U19=$AD$7,Rules!$G$6,U19=$AD$8,Rules!$G$7,U19="",)
B23: =AE3 -> Trey | C23: =IFS(C20=$AD$4,Rules!$G$3,C20=$AD$5,Rules!$G$4,C20=$AD$6,Rules!$G$5,C20=$AD$7,Rules!$G$6,C20=$AD$8,Rules!$G$7,C20="",) | D23: =IFS(D20=$AD$4,Rules!$G$3,D20=$AD$5,Rules!$G$4,D20=$AD$6,Rules!$G$5,D20=$AD$7,Rules!$G$6,D20=$AD$8,Rules!$G$7,D20="",) | E23: =IFS(E20=$AD$4,Rules!$G$3,E20=$AD$5,Rules!$G$4,E20=$AD$6,Rules!$G$5,E20=$AD$7,Rules!$G$6,E20=$AD$8,Rules!$G$7,E20="",) | F23: =IFS(F20=$AD$4,Rules!$G$3,F20=$AD$5,Rules!$G$4,F20=$AD$6,Rules!$G$5,F20=$AD$7,Rules!$G$6,F20=$AD$8,Rules!$G$7,F20="",) -> 1 | G23: =IFS(G20=$AD$4,Rules!$G$3,G20=$AD$5,Rules!$G$4,G20=$AD$6,Rules!$G$5,G20=$AD$7,Rules!$G$6,G20=$AD$8,Rules!$G$7,G20="",) | H23: =IFS(H20=$AD$4,Rules!$G$3,H20=$AD$5,Rules!$G$4,H20=$AD$6,Rules!$G$5,H20=$AD$7,Rules!$G$6,H20=$AD$8,Rules!$G$7,H20="",) | I23: =IFS(I20=$AD$4,Rules!$G$3,I20=$AD$5,Rules!$G$4,I20=$AD$6,Rules!$G$5,I20=$AD$7,Rules!$G$6,I20=$AD$8,Rules!$G$7,I20="",) -> 2 | J23: =IFS(J20=$AD$4,Rules!$G$3,J20=$AD$5,Rules!$G$4,J20=$AD$6,Rules!$G$5,J20=$AD$7,Rules!$G$6,J20=$AD$8,Rules!$G$7,J20="",) | K23: =IFS(K20=$AD$4,Rules!$G$3,K20=$AD$5,Rules!$G$4,K20=$AD$6,Rules!$G$5,K20=$AD$7,Rules!$G$6,K20=$AD$8,Rules!$G$7,K20="",) -> 1 | M23: =IFS(M20=$AD$4,Rules!$G$3,M20=$AD$5,Rules!$G$4,M20=$AD$6,Rules!$G$5,M20=$AD$7,Rules!$G$6,M20=$AD$8,Rules!$G$7,M20="",) | N23: =IFS(N20=$AD$4,Rules!$G$3,N20=$AD$5,Rules!$G$4,N20=$AD$6,Rules!$G$5,N20=$AD$7,Rules!$G$6,N20=$AD$8,Rules!$G$7,N20="",) | O23: =IFS(O20=$AD$4,Rules!$G$3,O20=$AD$5,Rules!$G$4,O20=$AD$6,Rules!$G$5,O20=$AD$7,Rules!$G$6,O20=$AD$8,Rules!$G$7,O20="",) | P23: =IFS(P20=$AD$4,Rules!$G$3,P20=$AD$5,Rules!$G$4,P20=$AD$6,Rules!$G$5,P20=$AD$7,Rules!$G$6,P20=$AD$8,Rules!$G$7,P20="",) | Q23: =IFS(Q20=$AD$4,Rules!$G$3,Q20=$AD$5,Rules!$G$4,Q20=$AD$6,Rules!$G$5,Q20=$AD$7,Rules!$G$6,Q20=$AD$8,Rules!$G$7,Q20="",) | R23: =IFS(R20=$AD$4,Rules!$G$3,R20=$AD$5,Rules!$G$4,R20=$AD$6,Rules!$G$5,R20=$AD$7,Rules!$G$6,R20=$AD$8,Rules!$G$7,R20="",) | S23: =IFS(S20=$AD$4,Rules!$G$3,S20=$AD$5,Rules!$G$4,S20=$AD$6,Rules!$G$5,S20=$AD$7,Rules!$G$6,S20=$AD$8,Rules!$G$7,S20="",) | T23: =IFS(T20=$AD$4,Rules!$G$3,T20=$AD$5,Rules!$G$4,T20=$AD$6,Rules!$G$5,T20=$AD$7,Rules!$G$6,T20=$AD$8,Rules!$G$7,T20="",) | U23: =IFS(U20=$AD$4,Rules!$G$3,U20=$AD$5,Rules!$G$4,U20=$AD$6,Rules!$G$5,U20=$AD$7,Rules!$G$6,U20=$AD$8,Rules!$G$7,U20="",) -> 1
B24: Trent Running Points Won | C24: =C22 -> 1 | D24: =D22+C24 -> 2 | E24: =E22+D24 -> 2 | F24: =F22+E24 -> 2 | G24: =G22+F24 -> 3 | H24: =H22+G24 -> 4 | I24: =I22+H24 -> 4 | J24: =J22+I24 -> 4 | K24: =K22+J24 -> 4 | ... U24: =U22+T24 -> 8
B25: Trey Running Points Won | C25: =C23 | D25: =D23+C25 -> 0 | E25: =E23+D25 -> 0 | F25: =F23+E25 -> 1 | G25: =G23+F25 -> 1 | H25: =H23+G25 -> 1 | I25: =I23+H25 -> 3 | J25: =J23+I25 -> 3 | K25: =K23+J25 -> 4 | ... U25: =U23+T25 -> 5

Sheet Deer Island CC - 2026-05-31
B2: Deer Island CC | C2: SCORECARD | AB2: Match Stats
B3: 46173 | C3: 1 | D3: 2 | E3: 3 | F3: 4 | G3: 5 | H3: 6 | I3: 7 | J3: 8 | K3: 9 | L3: Front 9 | M3: 10 | N3: 11 | O3: 12 | P3: 13 | Q3: 14 | R3: 15 | S3: 16 | T3: 17 | U3: 18 | V3: Back 9 | W3: PAR | Z3: To Par | AC3: =Rules!I3 -> Trent | AD3: 3 | AE3: =Rules!J3 -> Trey
B4: Par | C4: 4 | D4: 5 | E4: 3 | F4: 4 | G4: 4 | H4: 3 | I4: 4 | J4: 5 | K4: 4 | L4: =SUM(C4:K4) -> 36 | M4: 4 | N4: 4 | O4: 5 | P4: 3 | Q4: 4 | R4: 3 | S4: 5 | T4: 4 | U4: 4 | V4: =SUM(M4:U4) -> 36 | W4: =SUM(L4+V4) -> 72 | AB4: Eagles | AC4: =COUNTIF($C$6:$U$6,"🦅") -> 0 | AD4: 🦅 | AE4: =COUNTIF($C$8:$U$8,"🦅") -> 0
B5: =AC3 -> Trent | C5: 4 | D5: 6 | E5: 4 | F5: 4 | G5: 4 | H5: 3 | I5: 5 | J5: 5 | K5: 5 | L5: =SUM(C5:K5) -> 40 | M5: 6 | N5: 5 | O5: 6 | P5: 3 | Q5: 5 | R5: 3 | S5: 4 | T5: 5 | U5: 7 | V5: =SUM(M5:U5) -> 44 | W5: =SUM(L5+V5) -> 84 | X5: =IFS(W5>$W$4,"+",$W$4>W5,"") -> + | Y5: =W5-$W$4 -> 12 | Z5: =X5&Y5 -> +12 | AB5: Birdies | AC5: =COUNTIF($C$6:$U$6,"🐥") -> 1 | AD5: 🐥 | AE5: =COUNTIF($C$8:$U$8,"🐥") -> 1
C6: =IFS(C$4-C5=1,$AD$5,C$4-C5=2,$AD$4,C$4=C5,$AD$6,C$4-C5=-1,$AD$7,C$4-C5=-2,$AD$8,C$4-C5=-3,$AD$9) -> 🚩 | D6: =IFS(D$4-D5=1,$AD$5,D$4-D5=2,$AD$4,D$4=D5,$AD$6,D$4-D5=-1,$AD$7,D$4-D5=-2,$AD$8,D$4-D5=-3,$AD$9) -> 🧻 | E6: =IFS(E$4-E5=1,$AD$5,E$4-E5=2,$AD$4,E$4=E5,$AD$6,E$4-E5=-1,$AD$7,E$4-E5=-2,$AD$8,E$4-E5=-3,$AD$9) -> 🧻 | F6: =IFS(F$4-F5=1,$AD$5,F$4-F5=2,$AD$4,F$4=F5,$AD$6,F$4-F5=-1,$AD$7,F$4-F5=-2,$AD$8,F$4-F5=-3,$AD$9) -> 🚩 | G6: =IFS(G$4-G5=1,$AD$5,G$4-G5=2,$AD$4,G$4=G5,$AD$6,G$4-G5=-1,$AD$7,G$4-G5=-2,$AD$8,G$4-G5=-3,$AD$9) -> 🚩 | H6: =IFS(H$4-H5=1,$AD$5,H$4-H5=2,$AD$4,H$4=H5,$AD$6,H$4-H5=-1,$AD$7,H$4-H5=-2,$AD$8,H$4-H5=-3,$AD$9) -> 🚩 | I6: =IFS(I$4-I5=1,$AD$5,I$4-I5=2,$AD$4,I$4=I5,$AD$6,I$4-I5=-1,$AD$7,I$4-I5=-2,$AD$8,I$4-I5=-3,$AD$9) -> 🧻 | J6: =IFS(J$4-J5=1,$AD$5,J$4-J5=2,$AD$4,J$4=J5,$AD$6,J$4-J5=-1,$AD$7,J$4-J5=-2,$AD$8,J$4-J5=-3,$AD$9) -> 🚩 | K6: =IFS(K$4-K5=1,$AD$5,K$4-K5=2,$AD$4,K$4=K5,$AD$6,K$4-K5=-1,$AD$7,K$4-K5=-2,$AD$8,K$4-K5=-3,$AD$9) -> 🧻 | M6: =IFS(M$4-M5=1,$AD$5,M$4-M5=2,$AD$4,M$4=M5,$AD$6,M$4-M5=-1,$AD$7,M$4-M5=-2,$AD$8,M$4-M5=-3,$AD$9) -> 💩 | N6: =IFS(N$4-N5=1,$AD$5,N$4-N5=2,$AD$4,N$4=N5,$AD$6,N$4-N5=-1,$AD$7,N$4-N5=-2,$AD$8,N$4-N5=-3,$AD$9) -> 🧻 | O6: =IFS(O$4-O5=1,$AD$5,O$4-O5=2,$AD$4,O$4=O5,$AD$6,O$4-O5=-1,$AD$7,O$4-O5=-2,$AD$8,O$4-O5=-3,$AD$9) -> 🧻 | P6: =IFS(P$4-P5=1,$AD$5,P$4-P5=2,$AD$4,P$4=P5,$AD$6,P$4-P5=-1,$AD$7,P$4-P5=-2,$AD$8,P$4-P5=-3,$AD$9) -> 🚩 | Q6: =IFS(Q$4-Q5=1,$AD$5,Q$4-Q5=2,$AD$4,Q$4=Q5,$AD$6,Q$4-Q5=-1,$AD$7,Q$4-Q5=-2,$AD$8,Q$4-Q5=-3,$AD$9) -> 🧻 | R6: =IFS(R$4-R5=1,$AD$5,R$4-R5=2,$AD$4,R$4=R5,$AD$6,R$4-R5=-1,$AD$7,R$4-R5=-2,$AD$8,R$4-R5=-3,$AD$9) -> 🚩 | S6: =IFS(S$4-S5=1,$AD$5,S$4-S5=2,$AD$4,S$4=S5,$AD$6,S$4-S5=-1,$AD$7,S$4-S5=-2,$AD$8,S$4-S5=-3,$AD$9) -> 🐥 | T6: =IFS(T$4-T5=1,$AD$5,T$4-T5=2,$AD$4,T$4=T5,$AD$6,T$4-T5=-1,$AD$7,T$4-T5=-2,$AD$8,T$4-T5=-3,$AD$9) -> 🧻 | U6: =IFS(U$4-U5=1,$AD$5,U$4-U5=2,$AD$4,U$4=U5,$AD$6,U$4-U5=-1,$AD$7,U$4-U5=-2,$AD$8,U$4-U5=-3,$AD$9) -> ☠️ | AB6: Pars | AC6: =COUNTIF($C$6:$U$6,"🚩") -> 7 | AD6: 🚩 | AE6: =COUNTIF($C$8:$U$8,"🚩") -> 12
B7: =AE3 -> Trey | C7: 4 | D7: 5 | E7: 4 | F7: 6 | G7: 3 | H7: 3 | I7: 4 | J7: 5 | K7: 4 | L7: =SUM(C7:K7) -> 38 | M7: 4 | N7: 4 | O7: 6 | P7: 3 | Q7: 4 | R7: 4 | S7: 5 | T7: 5 | U7: 4 | V7: =SUM(M7:U7) -> 39 | W7: =SUM(L7+V7) -> 77 | X7: =IFS(W7>$W$4,"+",$W$4>W7,"") -> + | Y7: =W7-$W$4 -> 5 | Z7: =X7&Y7 -> +5 | AB7: Bogeys | AC7: =COUNTIF($C$6:$U$6,"🧻") -> 8 | AD7: 🧻 | AE7: =COUNTIF($C$8:$U$8,"🧻") -> 4
C8: =IFS(C$4-C7=1,$AD$5,C$4-C7=2,$AD$4,C$4=C7,$AD$6,C$4-C7=-1,$AD$7,C$4-C7=-2,$AD$8,C$4-C7=-3,$AD$9) -> 🚩 | D8: =IFS(D$4-D7=1,$AD$5,D$4-D7=2,$AD$4,D$4=D7,$AD$6,D$4-D7=-1,$AD$7,D$4-D7=-2,$AD$8,D$4-D7=-3,$AD$9) -> 🚩 | E8: =IFS(E$4-E7=1,$AD$5,E$4-E7=2,$AD$4,E$4=E7,$AD$6,E$4-E7=-1,$AD$7,E$4-E7=-2,$AD$8,E$4-E7=-3,$AD$9) -> 🧻 | F8: =IFS(F$4-F7=1,$AD$5,F$4-F7=2,$AD$4,F$4=F7,$AD$6,F$4-F7=-1,$AD$7,F$4-F7=-2,$AD$8,F$4-F7=-3,$AD$9) -> 💩 | G8: =IFS(G$4-G7=1,$AD$5,G$4-G7=2,$AD$4,G$4=G7,$AD$6,G$4-G7=-1,$AD$7,G$4-G7=-2,$AD$8,G$4-G7=-3,$AD$9) -> 🐥 | H8: =IFS(H$4-H7=1,$AD$5,H$4-H7=2,$AD$4,H$4=H7,$AD$6,H$4-H7=-1,$AD$7,H$4-H7=-2,$AD$8,H$4-H7=-3,$AD$9) -> 🚩 | I8: =IFS(I$4-I7=1,$AD$5,I$4-I7=2,$AD$4,I$4=I7,$AD$6,I$4-I7=-1,$AD$7,I$4-I7=-2,$AD$8,I$4-I7=-3,$AD$9) -> 🚩 | J8: =IFS(J$4-J7=1,$AD$5,J$4-J7=2,$AD$4,J$4=J7,$AD$6,J$4-J7=-1,$AD$7,J$4-J7=-2,$AD$8,J$4-J7=-3,$AD$9) -> 🚩 | K8: =IFS(K$4-K7=1,$AD$5,K$4-K7=2,$AD$4,K$4=K7,$AD$6,K$4-K7=-1,$AD$7,K$4-K7=-2,$AD$8,K$4-K7=-3,$AD$9) -> 🚩 | M8: =IFS(M$4-M7=1,$AD$5,M$4-M7=2,$AD$4,M$4=M7,$AD$6,M$4-M7=-1,$AD$7,M$4-M7=-2,$AD$8,M$4-M7=-3,$AD$9) -> 🚩 | N8: =IFS(N$4-N7=1,$AD$5,N$4-N7=2,$AD$4,N$4=N7,$AD$6,N$4-N7=-1,$AD$7,N$4-N7=-2,$AD$8,N$4-N7=-3,$AD$9) -> 🚩 | O8: =IFS(O$4-O7=1,$AD$5,O$4-O7=2,$AD$4,O$4=O7,$AD$6,O$4-O7=-1,$AD$7,O$4-O7=-2,$AD$8,O$4-O7=-3,$AD$9) -> 🧻 | P8: =IFS(P$4-P7=1,$AD$5,P$4-P7=2,$AD$4,P$4=P7,$AD$6,P$4-P7=-1,$AD$7,P$4-P7=-2,$AD$8,P$4-P7=-3,$AD$9) -> 🚩 | Q8: =IFS(Q$4-Q7=1,$AD$5,Q$4-Q7=2,$AD$4,Q$4=Q7,$AD$6,Q$4-Q7=-1,$AD$7,Q$4-Q7=-2,$AD$8,Q$4-Q7=-3,$AD$9) -> 🚩 | R8: =IFS(R$4-R7=1,$AD$5,R$4-R7=2,$AD$4,R$4=R7,$AD$6,R$4-R7=-1,$AD$7,R$4-R7=-2,$AD$8,R$4-R7=-3,$AD$9) -> 🧻 | S8: =IFS(S$4-S7=1,$AD$5,S$4-S7=2,$AD$4,S$4=S7,$AD$6,S$4-S7=-1,$AD$7,S$4-S7=-2,$AD$8,S$4-S7=-3,$AD$9) -> 🚩 | T8: =IFS(T$4-T7=1,$AD$5,T$4-T7=2,$AD$4,T$4=T7,$AD$6,T$4-T7=-1,$AD$7,T$4-T7=-2,$AD$8,T$4-T7=-3,$AD$9) -> 🧻 | U8: =IFS(U$4-U7=1,$AD$5,U$4-U7=2,$AD$4,U$4=U7,$AD$6,U$4-U7=-1,$AD$7,U$4-U7=-2,$AD$8,U$4-U7=-3,$AD$9) -> 🚩 | AB8: Doubles | AC8: =COUNTIF($C$6:$U$6,"💩") -> 1 | AD8: 💩 | AE8: =COUNTIF($C$8:$U$8,"💩") -> 1
AB9: Triples | AC9: =COUNTIF($C$6:$U$6,"☠️") -> 1 | AD9: ☠️ | AE9: =COUNTIF($C$8:$U$8,"☠️") -> 0
AB10: Holes Won | AC10: =Count(C22:U22) -> 3 | AE10: =Count(C23:U23) -> 8
AB11: Points Won | AC11: =U24 -> 4 | AE11: =U25 -> 9
AB12: Result | AC12: =IFS(AC11>AE11,AC3,AE11>AC11,AE3,AC11=AE11,"AS") -> Trey | AD12: =IFS(AC11>AE11,AC11-AE11,AE11>AC11,AE11-AC11,AC11=AE11,"AS") -> 5 | AE12: =AD12*AD3 -> 15
B18: Running Match Score | C18: =IFS(C24>C25,C24-C25,C25>C24,C25-C24,C24=C25,"AS") -> AS | D18: =IFS(D24>D25,D24-D25,D25>D24,D25-D24,D24=D25,"AS") -> 1 | E18: =IFS(E24>E25,E24-E25,E25>E24,E25-E24,E24=E25,"AS") -> 1 | F18: =IFS(F24>F25,F24-F25,F25>F24,F25-F24,F24=F25,"AS") -> AS | G18: =IFS(G24>G25,G24-G25,G25>G24,G25-G24,G24=G25,"AS") -> 2 | H18: =IFS(H24>H25,H24-H25,H25>H24,H25-H24,H24=H25,"AS") -> 2 | I18: =IFS(I24>I25,I24-I25,I25>I24,I25-I24,I24=I25,"AS") -> 3 | J18: =IFS(J24>J25,J24-J25,J25>J24,J25-J24,J24=J25,"AS") -> 3 | ... U18: =IFS(U24>U25,U24-U25,U25>U24,U25-U24,U24=U25,"AS") -> 5
B19: =AC3 -> Trent | C19: =IF(C$5<C$7,C6,) | D19: =IF(D5<D7,D6,) | E19: =IF(E5<E7,E6,) | F19: =IF(F5<F7,F6,) -> 🚩 | G19: =IF(G5<G7,G6,) | H19: =IF(H5<H7,H6,) | I19: =IF(I5<I7,I6,) | J19: =IF(J5<J7,J6,) | K19: =IF(K5<K7,K6,) | M19: =IF(M5<M7,M6,) | N19: =IF(N5<N7,N6,) | O19: =IF(O5<O7,O6,) | P19: =IF(P5<P7,P6,) | Q19: =IF(Q5<Q7,Q6,) | R19: =IF(R5<R7,R6,) -> 🚩 | S19: =IF(S5<S7,S6,) -> 🐥 | T19: =IF(T5<T7,T6,) | U19: =IF(U5<U7,U6,)
B20: =AE3 -> Trey | C20: =IF(C$5>C$7,C8,) | D20: =IF(D$5>D$7,D8,) -> 🚩 | E20: =IF(E$5>E$7,E8,) | F20: =IF(F$5>F$7,F8,) | G20: =IF(G$5>G$7,G8,) -> 🐥 | H20: =IF(H$5>H$7,H8,) | I20: =IF(I$5>I$7,I8,) -> 🚩 | J20: =IF(J$5>J$7,J8,) | K20: =IF(K$5>K$7,K8,) -> 🚩 | M20: =IF(M$5>M$7,M8,) -> 🚩 | N20: =IF(N$5>N$7,N8,) -> 🚩 | O20: =IF(O$5>O$7,O8,) | P20: =IF(P$5>P$7,P8,) | Q20: =IF(Q$5>Q$7,Q8,) -> 🚩 | R20: =IF(R$5>R$7,R8,) | S20: =IF(S$5>S$7,S8,) | T20: =IF(T$5>T$7,T8,) | U20: =IF(U$5>U$7,U8,) -> 🚩
B21: Match Points Awarded
B22: =AC3 -> Trent | C22: =IFS(C19=$AD$4,Rules!$G$3,C19=$AD$5,Rules!$G$4,C19=$AD$6,Rules!$G$5,C19=$AD$7,Rules!$G$6,C19=$AD$8,Rules!$G$7,C19="",) | D22: =IFS(D19=$AD$4,Rules!$G$3,D19=$AD$5,Rules!$G$4,D19=$AD$6,Rules!$G$5,D19=$AD$7,Rules!$G$6,D19=$AD$8,Rules!$G$7,D19="",) | E22: =IFS(E19=$AD$4,Rules!$G$3,E19=$AD$5,Rules!$G$4,E19=$AD$6,Rules!$G$5,E19=$AD$7,Rules!$G$6,E19=$AD$8,Rules!$G$7,E19="",) | F22: =IFS(F19=$AD$4,Rules!$G$3,F19=$AD$5,Rules!$G$4,F19=$AD$6,Rules!$G$5,F19=$AD$7,Rules!$G$6,F19=$AD$8,Rules!$G$7,F19="",) -> 1 | G22: =IFS(G19=$AD$4,Rules!$G$3,G19=$AD$5,Rules!$G$4,G19=$AD$6,Rules!$G$5,G19=$AD$7,Rules!$G$6,G19=$AD$8,Rules!$G$7,G19="",) | H22: =IFS(H19=$AD$4,Rules!$G$3,H19=$AD$5,Rules!$G$4,H19=$AD$6,Rules!$G$5,H19=$AD$7,Rules!$G$6,H19=$AD$8,Rules!$G$7,H19="",) | I22: =IFS(I19=$AD$4,Rules!$G$3,I19=$AD$5,Rules!$G$4,I19=$AD$6,Rules!$G$5,I19=$AD$7,Rules!$G$6,I19=$AD$8,Rules!$G$7,I19="",) | J22: =IFS(J19=$AD$4,Rules!$G$3,J19=$AD$5,Rules!$G$4,J19=$AD$6,Rules!$G$5,J19=$AD$7,Rules!$G$6,J19=$AD$8,Rules!$G$7,J19="",) | K22: =IFS(K19=$AD$4,Rules!$G$3,K19=$AD$5,Rules!$G$4,K19=$AD$6,Rules!$G$5,K19=$AD$7,Rules!$G$6,K19=$AD$8,Rules!$G$7,K19="",) | M22: =IFS(M19=$AD$4,Rules!$G$3,M19=$AD$5,Rules!$G$4,M19=$AD$6,Rules!$G$5,M19=$AD$7,Rules!$G$6,M19=$AD$8,Rules!$G$7,M19="",) | N22: =IFS(N19=$AD$4,Rules!$G$3,N19=$AD$5,Rules!$G$4,N19=$AD$6,Rules!$G$5,N19=$AD$7,Rules!$G$6,N19=$AD$8,Rules!$G$7,N19="",) | O22: =IFS(O19=$AD$4,Rules!$G$3,O19=$AD$5,Rules!$G$4,O19=$AD$6,Rules!$G$5,O19=$AD$7,Rules!$G$6,O19=$AD$8,Rules!$G$7,O19="",) | P22: =IFS(P19=$AD$4,Rules!$G$3,P19=$AD$5,Rules!$G$4,P19=$AD$6,Rules!$G$5,P19=$AD$7,Rules!$G$6,P19=$AD$8,Rules!$G$7,P19="",) | Q22: =IFS(Q19=$AD$4,Rules!$G$3,Q19=$AD$5,Rules!$G$4,Q19=$AD$6,Rules!$G$5,Q19=$AD$7,Rules!$G$6,Q19=$AD$8,Rules!$G$7,Q19="",) | R22: =IFS(R19=$AD$4,Rules!$G$3,R19=$AD$5,Rules!$G$4,R19=$AD$6,Rules!$G$5,R19=$AD$7,Rules!$G$6,R19=$AD$8,Rules!$G$7,R19="",) -> 1 | S22: =IFS(S19=$AD$4,Rules!$G$3,S19=$AD$5,Rules!$G$4,S19=$AD$6,Rules!$G$5,S19=$AD$7,Rules!$G$6,S19=$AD$8,Rules!$G$7,S19="",) -> 2 | T22: =IFS(T19=$AD$4,Rules!$G$3,T19=$AD$5,Rules!$G$4,T19=$AD$6,Rules!$G$5,T19=$AD$7,Rules!$G$6,T19=$AD$8,Rules!$G$7,T19="",) | U22: =IFS(U19=$AD$4,Rules!$G$3,U19=$AD$5,Rules!$G$4,U19=$AD$6,Rules!$G$5,U19=$AD$7,Rules!$G$6,U19=$AD$8,Rules!$G$7,U19="",)
B23: =AE3 -> Trey | C23: =IFS(C20=$AD$4,Rules!$G$3,C20=$AD$5,Rules!$G$4,C20=$AD$6,Rules!$G$5,C20=$AD$7,Rules!$G$6,C20=$AD$8,Rules!$G$7,C20="",) | D23: =IFS(D20=$AD$4,Rules!$G$3,D20=$AD$5,Rules!$G$4,D20=$AD$6,Rules!$G$5,D20=$AD$7,Rules!$G$6,D20=$AD$8,Rules!$G$7,D20="",) -> 1 | E23: =IFS(E20=$AD$4,Rules!$G$3,E20=$AD$5,Rules!$G$4,E20=$AD$6,Rules!$G$5,E20=$AD$7,Rules!$G$6,E20=$AD$8,Rules!$G$7,E20="",) | F23: =IFS(F20=$AD$4,Rules!$G$3,F20=$AD$5,Rules!$G$4,F20=$AD$6,Rules!$G$5,F20=$AD$7,Rules!$G$6,F20=$AD$8,Rules!$G$7,F20="",) | G23: =IFS(G20=$AD$4,Rules!$G$3,G20=$AD$5,Rules!$G$4,G20=$AD$6,Rules!$G$5,G20=$AD$7,Rules!$G$6,G20=$AD$8,Rules!$G$7,G20="",) -> 2 | H23: =IFS(H20=$AD$4,Rules!$G$3,H20=$AD$5,Rules!$G$4,H20=$AD$6,Rules!$G$5,H20=$AD$7,Rules!$G$6,H20=$AD$8,Rules!$G$7,H20="",) | I23: =IFS(I20=$AD$4,Rules!$G$3,I20=$AD$5,Rules!$G$4,I20=$AD$6,Rules!$G$5,I20=$AD$7,Rules!$G$6,I20=$AD$8,Rules!$G$7,I20="",) -> 1 | J23: =IFS(J20=$AD$4,Rules!$G$3,J20=$AD$5,Rules!$G$4,J20=$AD$6,Rules!$G$5,J20=$AD$7,Rules!$G$6,J20=$AD$8,Rules!$G$7,J20="",) | K23: =IFS(K20=$AD$4,Rules!$G$3,K20=$AD$5,Rules!$G$4,K20=$AD$6,Rules!$G$5,K20=$AD$7,Rules!$G$6,K20=$AD$8,Rules!$G$7,K20="",) -> 1 | M23: =IFS(M20=$AD$4,Rules!$G$3,M20=$AD$5,Rules!$G$4,M20=$AD$6,Rules!$G$5,M20=$AD$7,Rules!$G$6,M20=$AD$8,Rules!$G$7,M20="",) -> 1 | N23: =IFS(N20=$AD$4,Rules!$G$3,N20=$AD$5,Rules!$G$4,N20=$AD$6,Rules!$G$5,N20=$AD$7,Rules!$G$6,N20=$AD$8,Rules!$G$7,N20="",) -> 1 | O23: =IFS(O20=$AD$4,Rules!$G$3,O20=$AD$5,Rules!$G$4,O20=$AD$6,Rules!$G$5,O20=$AD$7,Rules!$G$6,O20=$AD$8,Rules!$G$7,O20="",) | P23: =IFS(P20=$AD$4,Rules!$G$3,P20=$AD$5,Rules!$G$4,P20=$AD$6,Rules!$G$5,P20=$AD$7,Rules!$G$6,P20=$AD$8,Rules!$G$7,P20="",) | Q23: =IFS(Q20=$AD$4,Rules!$G$3,Q20=$AD$5,Rules!$G$4,Q20=$AD$6,Rules!$G$5,Q20=$AD$7,Rules!$G$6,Q20=$AD$8,Rules!$G$7,Q20="",) -> 1 | R23: =IFS(R20=$AD$4,Rules!$G$3,R20=$AD$5,Rules!$G$4,R20=$AD$6,Rules!$G$5,R20=$AD$7,Rules!$G$6,R20=$AD$8,Rules!$G$7,R20="",) | S23: =IFS(S20=$AD$4,Rules!$G$3,S20=$AD$5,Rules!$G$4,S20=$AD$6,Rules!$G$5,S20=$AD$7,Rules!$G$6,S20=$AD$8,Rules!$G$7,S20="",) | T23: =IFS(T20=$AD$4,Rules!$G$3,T20=$AD$5,Rules!$G$4,T20=$AD$6,Rules!$G$5,T20=$AD$7,Rules!$G$6,T20=$AD$8,Rules!$G$7,T20="",) | U23: =IFS(U20=$AD$4,Rules!$G$3,U20=$AD$5,Rules!$G$4,U20=$AD$6,Rules!$G$5,U20=$AD$7,Rules!$G$6,U20=$AD$8,Rules!$G$7,U20="",) -> 1
B24: Trent Running Points Won | C24: =C22 | D24: =D22+C24 -> 0 | E24: =E22+D24 -> 0 | F24: =F22+E24 -> 1 | G24: =G22+F24 -> 1 | H24: =H22+G24 -> 1 | I24: =I22+H24 -> 1 | J24: =J22+I24 -> 1 | K24: =K22+J24 -> 1 | ... U24: =U22+T24 -> 4
B25: Trey Running Points Won | C25: =C23 | D25: =D23+C25 -> 1 | E25: =E23+D25 -> 1 | F25: =F23+E25 -> 1 | G25: =G23+F25 -> 3 | H25: =H23+G25 -> 3 | I25: =I23+H25 -> 4 | J25: =J23+I25 -> 4 | K25: =K23+J25 -> 5 | ... U25: =U23+T25 -> 9

Sheet Marsh Landing CC - 2026-05-23
B2: Marsh Landing CC | C2: SCORECARD | AB2: Match Stats
B3: 46165 | C3: 1 | D3: 2 | E3: 3 | F3: 4 | G3: 5 | H3: 6 | I3: 7 | J3: 8 | K3: 9 | L3: Front 9 | M3: 10 | N3: 11 | O3: 12 | P3: 13 | Q3: 14 | R3: 15 | S3: 16 | T3: 17 | U3: 18 | V3: Back 9 | W3: PAR | Z3: To Par | AC3: =Rules!I3 -> Trent | AD3: 5 | AE3: =Rules!J3 -> Trey
B4: Par | C4: 4 | D4: 3 | E4: 4 | F4: 4 | G4: 5 | H4: 4 | I4: 4 | J4: 3 | K4: 5 | L4: =SUM(C4:K4) -> 36 | M4: 4 | N4: 4 | O4: 3 | P4: 4 | Q4: 4 | R4: 5 | S4: 3 | T4: 5 | U4: 4 | V4: =SUM(M4:U4) -> 36 | W4: =SUM(L4+V4) -> 72 | AB4: Eagles | AC4: =COUNTIF($C$6:$U$6,"🦅") -> 0 | AD4: 🦅 | AE4: =COUNTIF($C$8:$U$8,"🦅") -> 0
B5: =AC3 -> Trent | C5: 4 | D5: 5 | E5: 5 | F5: 5 | G5: 6 | H5: 4 | I5: 6 | J5: 4 | K5: 4 | L5: =SUM(C5:K5) -> 43 | M5: 5 | N5: 5 | O5: 3 | P5: 4 | Q5: 5 | R5: 6 | S5: 4 | T5: 5 | U5: 5 | V5: =SUM(M5:U5) -> 42 | W5: =SUM(L5+V5) -> 85 | X5: =IFS(W5>$W$4,"+",$W$4>W5,"") -> + | Y5: =W5-$W$4 -> 13 | Z5: =X5&Y5 -> +13 | AB5: Birdies | AC5: =COUNTIF($C$6:$U$6,"🐥") -> 1 | AD5: 🐥 | AE5: =COUNTIF($C$8:$U$8,"🐥") -> 0
C6: =IFS(C$4-C5=1,$AD$5,C$4-C5=2,$AD$4,C$4=C5,$AD$6,C$4-C5=-1,$AD$7,C$4-C5=-2,$AD$8,C$4-C5=-3,$AD$9) -> 🚩 | D6: =IFS(D$4-D5=1,$AD$5,D$4-D5=2,$AD$4,D$4=D5,$AD$6,D$4-D5=-1,$AD$7,D$4-D5=-2,$AD$8,D$4-D5=-3,$AD$9) -> 💩 | E6: =IFS(E$4-E5=1,$AD$5,E$4-E5=2,$AD$4,E$4=E5,$AD$6,E$4-E5=-1,$AD$7,E$4-E5=-2,$AD$8,E$4-E5=-3,$AD$9) -> 🧻 | F6: =IFS(F$4-F5=1,$AD$5,F$4-F5=2,$AD$4,F$4=F5,$AD$6,F$4-F5=-1,$AD$7,F$4-F5=-2,$AD$8,F$4-F5=-3,$AD$9) -> 🧻 | G6: =IFS(G$4-G5=1,$AD$5,G$4-G5=2,$AD$4,G$4=G5,$AD$6,G$4-G5=-1,$AD$7,G$4-G5=-2,$AD$8,G$4-G5=-3,$AD$9) -> 🧻 | H6: =IFS(H$4-H5=1,$AD$5,H$4-H5=2,$AD$4,H$4=H5,$AD$6,H$4-H5=-1,$AD$7,H$4-H5=-2,$AD$8,H$4-H5=-3,$AD$9) -> 🚩 | I6: =IFS(I$4-I5=1,$AD$5,I$4-I5=2,$AD$4,I$4=I5,$AD$6,I$4-I5=-1,$AD$7,I$4-I5=-2,$AD$8,I$4-I5=-3,$AD$9) -> 💩 | J6: =IFS(J$4-J5=1,$AD$5,J$4-J5=2,$AD$4,J$4=J5,$AD$6,J$4-J5=-1,$AD$7,J$4-J5=-2,$AD$8,J$4-J5=-3,$AD$9) -> 🧻 | K6: =IFS(K$4-K5=1,$AD$5,K$4-K5=2,$AD$4,K$4=K5,$AD$6,K$4-K5=-1,$AD$7,K$4-K5=-2,$AD$8,K$4-K5=-3,$AD$9) -> 🐥 | M6: =IFS(M$4-M5=1,$AD$5,M$4-M5=2,$AD$4,M$4=M5,$AD$6,M$4-M5=-1,$AD$7,M$4-M5=-2,$AD$8,M$4-M5=-3,$AD$9) -> 🧻 | N6: =IFS(N$4-N5=1,$AD$5,N$4-N5=2,$AD$4,N$4=N5,$AD$6,N$4-N5=-1,$AD$7,N$4-N5=-2,$AD$8,N$4-N5=-3,$AD$9) -> 🧻 | O6: =IFS(O$4-O5=1,$AD$5,O$4-O5=2,$AD$4,O$4=O5,$AD$6,O$4-O5=-1,$AD$7,O$4-O5=-2,$AD$8,O$4-O5=-3,$AD$9) -> 🚩 | P6: =IFS(P$4-P5=1,$AD$5,P$4-P5=2,$AD$4,P$4=P5,$AD$6,P$4-P5=-1,$AD$7,P$4-P5=-2,$AD$8,P$4-P5=-3,$AD$9) -> 🚩 | Q6: =IFS(Q$4-Q5=1,$AD$5,Q$4-Q5=2,$AD$4,Q$4=Q5,$AD$6,Q$4-Q5=-1,$AD$7,Q$4-Q5=-2,$AD$8,Q$4-Q5=-3,$AD$9) -> 🧻 | R6: =IFS(R$4-R5=1,$AD$5,R$4-R5=2,$AD$4,R$4=R5,$AD$6,R$4-R5=-1,$AD$7,R$4-R5=-2,$AD$8,R$4-R5=-3,$AD$9) -> 🧻 | S6: =IFS(S$4-S5=1,$AD$5,S$4-S5=2,$AD$4,S$4=S5,$AD$6,S$4-S5=-1,$AD$7,S$4-S5=-2,$AD$8,S$4-S5=-3,$AD$9) -> 🧻 | T6: =IFS(T$4-T5=1,$AD$5,T$4-T5=2,$AD$4,T$4=T5,$AD$6,T$4-T5=-1,$AD$7,T$4-T5=-2,$AD$8,T$4-T5=-3,$AD$9) -> 🚩 | U6: =IFS(U$4-U5=1,$AD$5,U$4-U5=2,$AD$4,U$4=U5,$AD$6,U$4-U5=-1,$AD$7,U$4-U5=-2,$AD$8,U$4-U5=-3,$AD$9) -> 🧻 | AB6: Pars | AC6: =COUNTIF($C$6:$U$6,"🚩") -> 5 | AD6: 🚩 | AE6: =COUNTIF($C$8:$U$8,"🚩") -> 2
B7: =AE3 -> Trey | C7: 6 | D7: 5 | E7: 5 | F7: 6 | G7: 7 | H7: 6 | I7: 5 | J7: 4 | K7: 7 | L7: =SUM(C7:K7) -> 51 | M7: 6 | N7: 7 | O7: 3 | P7: 5 | Q7: 5 | R7: 6 | S7: 3 | T7: 7 | U7: 5 | V7: =SUM(M7:U7) -> 47 | W7: =SUM(L7+V7) -> 98 | X7: =IFS(W7>$W$4,"+",$W$4>W7,"") -> + | Y7: =W7-$W$4 -> 26 | Z7: =X7&Y7 -> +26 | AB7: Bogeys | AC7: =COUNTIF($C$6:$U$6,"🧻") -> 10 | AD7: 🧻 | AE7: =COUNTIF($C$8:$U$8,"🧻") -> 7
C8: =IFS(C$4-C7=1,$AD$5,C$4-C7=2,$AD$4,C$4=C7,$AD$6,C$4-C7=-1,$AD$7,C$4-C7=-2,$AD$8,C$4-C7=-3,$AD$9) -> 💩 | D8: =IFS(D$4-D7=1,$AD$5,D$4-D7=2,$AD$4,D$4=D7,$AD$6,D$4-D7=-1,$AD$7,D$4-D7=-2,$AD$8,D$4-D7=-3,$AD$9) -> 💩 | E8: =IFS(E$4-E7=1,$AD$5,E$4-E7=2,$AD$4,E$4=E7,$AD$6,E$4-E7=-1,$AD$7,E$4-E7=-2,$AD$8,E$4-E7=-3,$AD$9) -> 🧻 | F8: =IFS(F$4-F7=1,$AD$5,F$4-F7=2,$AD$4,F$4=F7,$AD$6,F$4-F7=-1,$AD$7,F$4-F7=-2,$AD$8,F$4-F7=-3,$AD$9) -> 💩 | G8: =IFS(G$4-G7=1,$AD$5,G$4-G7=2,$AD$4,G$4=G7,$AD$6,G$4-G7=-1,$AD$7,G$4-G7=-2,$AD$8,G$4-G7=-3,$AD$9) -> 💩 | H8: =IFS(H$4-H7=1,$AD$5,H$4-H7=2,$AD$4,H$4=H7,$AD$6,H$4-H7=-1,$AD$7,H$4-H7=-2,$AD$8,H$4-H7=-3,$AD$9) -> 💩 | I8: =IFS(I$4-I7=1,$AD$5,I$4-I7=2,$AD$4,I$4=I7,$AD$6,I$4-I7=-1,$AD$7,I$4-I7=-2,$AD$8,I$4-I7=-3,$AD$9) -> 🧻 | J8: =IFS(J$4-J7=1,$AD$5,J$4-J7=2,$AD$4,J$4=J7,$AD$6,J$4-J7=-1,$AD$7,J$4-J7=-2,$AD$8,J$4-J7=-3,$AD$9) -> 🧻 | K8: =IFS(K$4-K7=1,$AD$5,K$4-K7=2,$AD$4,K$4=K7,$AD$6,K$4-K7=-1,$AD$7,K$4-K7=-2,$AD$8,K$4-K7=-3,$AD$9) -> 💩 | M8: =IFS(M$4-M7=1,$AD$5,M$4-M7=2,$AD$4,M$4=M7,$AD$6,M$4-M7=-1,$AD$7,M$4-M7=-2,$AD$8,M$4-M7=-3,$AD$9) -> 💩 | N8: =IFS(N$4-N7=1,$AD$5,N$4-N7=2,$AD$4,N$4=N7,$AD$6,N$4-N7=-1,$AD$7,N$4-N7=-2,$AD$8,N$4-N7=-3,$AD$9) -> ☠️ | O8: =IFS(O$4-O7=1,$AD$5,O$4-O7=2,$AD$4,O$4=O7,$AD$6,O$4-O7=-1,$AD$7,O$4-O7=-2,$AD$8,O$4-O7=-3,$AD$9) -> 🚩 | P8: =IFS(P$4-P7=1,$AD$5,P$4-P7=2,$AD$4,P$4=P7,$AD$6,P$4-P7=-1,$AD$7,P$4-P7=-2,$AD$8,P$4-P7=-3,$AD$9) -> 🧻 | Q8: =IFS(Q$4-Q7=1,$AD$5,Q$4-Q7=2,$AD$4,Q$4=Q7,$AD$6,Q$4-Q7=-1,$AD$7,Q$4-Q7=-2,$AD$8,Q$4-Q7=-3,$AD$9) -> 🧻 | R8: =IFS(R$4-R7=1,$AD$5,R$4-R7=2,$AD$4,R$4=R7,$AD$6,R$4-R7=-1,$AD$7,R$4-R7=-2,$AD$8,R$4-R7=-3,$AD$9) -> 🧻 | S8: =IFS(S$4-S7=1,$AD$5,S$4-S7=2,$AD$4,S$4=S7,$AD$6,S$4-S7=-1,$AD$7,S$4-S7=-2,$AD$8,S$4-S7=-3,$AD$9) -> 🚩 | T8: =IFS(T$4-T7=1,$AD$5,T$4-T7=2,$AD$4,T$4=T7,$AD$6,T$4-T7=-1,$AD$7,T$4-T7=-2,$AD$8,T$4-T7=-3,$AD$9) -> 💩 | U8: =IFS(U$4-U7=1,$AD$5,U$4-U7=2,$AD$4,U$4=U7,$AD$6,U$4-U7=-1,$AD$7,U$4-U7=-2,$AD$8,U$4-U7=-3,$AD$9) -> 🧻 | AB8: Doubles | AC8: =COUNTIF($C$6:$U$6,"💩") -> 2 | AD8: 💩 | AE8: =COUNTIF($C$8:$U$8,"💩") -> 8
AB9: Triples | AC9: =COUNTIF($C$6:$U$6,"☠️") -> 0 | AD9: ☠️ | AE9: =COUNTIF($C$8:$U$8,"☠️") -> 1
AB10: Holes Won | AC10: =Count(C22:U22) -> 9 | AE10: =Count(C23:U23) -> 2
AB11: Points Won | AC11: =U24 -> 10 | AE11: =U25 -> 2
AB12: Result | AC12: =IFS(AC11>AE11,AC3,AE11>AC11,AE3,AC11=AE11,"AS") -> Trent | AD12: =IFS(AC11>AE11,AC11-AE11,AE11>AC11,AE11-AC11,AC11=AE11,"AS") -> 8 | AE12: =AD12*AD3 -> 40
B18: Running Match Score | C18: =IFS(C24>C25,C24-C25,C25>C24,C25-C24,C24=C25,"AS") -> 1 | D18: =IFS(D24>D25,D24-D25,D25>D24,D25-D24,D24=D25,"AS") -> 1 | E18: =IFS(E24>E25,E24-E25,E25>E24,E25-E24,E24=E25,"AS") -> 1 | F18: =IFS(F24>F25,F24-F25,F25>F24,F25-F24,F24=F25,"AS") -> 2 | G18: =IFS(G24>G25,G24-G25,G25>G24,G25-G24,G24=G25,"AS") -> 3 | H18: =IFS(H24>H25,H24-H25,H25>H24,H25-H24,H24=H25,"AS") -> 4 | I18: =IFS(I24>I25,I24-I25,I25>I24,I25-I24,I24=I25,"AS") -> 3 | J18: =IFS(J24>J25,J24-J25,J25>J24,J25-J24,J24=J25,"AS") -> 3 | ... U18: =IFS(U24>U25,U24-U25,U25>U24,U25-U24,U24=U25,"AS") -> 8
B19: =AC3 -> Trent | C19: =IF(C$5<C$7,C6,) -> 🚩 | D19: =IF(D5<D7,D6,) | E19: =IF(E5<E7,E6,) | F19: =IF(F5<F7,F6,) -> 🧻 | G19: =IF(G5<G7,G6,) -> 🧻 | H19: =IF(H5<H7,H6,) -> 🚩 | I19: =IF(I5<I7,I6,) | J19: =IF(J5<J7,J6,) | K19: =IF(K5<K7,K6,) -> 🐥 | M19: =IF(M5<M7,M6,) -> 🧻 | N19: =IF(N5<N7,N6,) -> 🧻 | O19: =IF(O5<O7,O6,) | P19: =IF(P5<P7,P6,) -> 🚩 | Q19: =IF(Q5<Q7,Q6,) | R19: =IF(R5<R7,R6,) | S19: =IF(S5<S7,S6,) | T19: =IF(T5<T7,T6,) -> 🚩 | U19: =IF(U5<U7,U6,)
B20: =AE3 -> Trey | C20: =IF(C$5>C$7,C8,) | D20: =IF(D$5>D$7,D8,) | E20: =IF(E$5>E$7,E8,) | F20: =IF(F$5>F$7,F8,) | G20: =IF(G$5>G$7,G8,) | H20: =IF(H$5>H$7,H8,) | I20: =IF(I$5>I$7,I8,) -> 🧻 | J20: =IF(J$5>J$7,J8,) | K20: =IF(K$5>K$7,K8,) | M20: =IF(M$5>M$7,M8,) | N20: =IF(N$5>N$7,N8,) | O20: =IF(O$5>O$7,O8,) | P20: =IF(P$5>P$7,P8,) | Q20: =IF(Q$5>Q$7,Q8,) | R20: =IF(R$5>R$7,R8,) | S20: =IF(S$5>S$7,S8,) -> 🚩 | T20: =IF(T$5>T$7,T8,) | U20: =IF(U$5>U$7,U8,)
B21: Match Points Awarded
B22: =AC3 -> Trent | C22: =IFS(C19=$AD$4,Rules!$G$3,C19=$AD$5,Rules!$G$4,C19=$AD$6,Rules!$G$5,C19=$AD$7,Rules!$G$6,C19=$AD$8,Rules!$G$7,C19="",) -> 1 | D22: =IFS(D19=$AD$4,Rules!$G$3,D19=$AD$5,Rules!$G$4,D19=$AD$6,Rules!$G$5,D19=$AD$7,Rules!$G$6,D19=$AD$8,Rules!$G$7,D19="",) | E22: =IFS(E19=$AD$4,Rules!$G$3,E19=$AD$5,Rules!$G$4,E19=$AD$6,Rules!$G$5,E19=$AD$7,Rules!$G$6,E19=$AD$8,Rules!$G$7,E19="",) | F22: =IFS(F19=$AD$4,Rules!$G$3,F19=$AD$5,Rules!$G$4,F19=$AD$6,Rules!$G$5,F19=$AD$7,Rules!$G$6,F19=$AD$8,Rules!$G$7,F19="",) -> 1 | G22: =IFS(G19=$AD$4,Rules!$G$3,G19=$AD$5,Rules!$G$4,G19=$AD$6,Rules!$G$5,G19=$AD$7,Rules!$G$6,G19=$AD$8,Rules!$G$7,G19="",) -> 1 | H22: =IFS(H19=$AD$4,Rules!$G$3,H19=$AD$5,Rules!$G$4,H19=$AD$6,Rules!$G$5,H19=$AD$7,Rules!$G$6,H19=$AD$8,Rules!$G$7,H19="",) -> 1 | I22: =IFS(I19=$AD$4,Rules!$G$3,I19=$AD$5,Rules!$G$4,I19=$AD$6,Rules!$G$5,I19=$AD$7,Rules!$G$6,I19=$AD$8,Rules!$G$7,I19="",) | J22: =IFS(J19=$AD$4,Rules!$G$3,J19=$AD$5,Rules!$G$4,J19=$AD$6,Rules!$G$5,J19=$AD$7,Rules!$G$6,J19=$AD$8,Rules!$G$7,J19="",) | K22: =IFS(K19=$AD$4,Rules!$G$3,K19=$AD$5,Rules!$G$4,K19=$AD$6,Rules!$G$5,K19=$AD$7,Rules!$G$6,K19=$AD$8,Rules!$G$7,K19="",) -> 2 | M22: =IFS(M19=$AD$4,Rules!$G$3,M19=$AD$5,Rules!$G$4,M19=$AD$6,Rules!$G$5,M19=$AD$7,Rules!$G$6,M19=$AD$8,Rules!$G$7,M19="",) -> 1 | N22: =IFS(N19=$AD$4,Rules!$G$3,N19=$AD$5,Rules!$G$4,N19=$AD$6,Rules!$G$5,N19=$AD$7,Rules!$G$6,N19=$AD$8,Rules!$G$7,N19="",) -> 1 | O22: =IFS(O19=$AD$4,Rules!$G$3,O19=$AD$5,Rules!$G$4,O19=$AD$6,Rules!$G$5,O19=$AD$7,Rules!$G$6,O19=$AD$8,Rules!$G$7,O19="",) | P22: =IFS(P19=$AD$4,Rules!$G$3,P19=$AD$5,Rules!$G$4,P19=$AD$6,Rules!$G$5,P19=$AD$7,Rules!$G$6,P19=$AD$8,Rules!$G$7,P19="",) -> 1 | Q22: =IFS(Q19=$AD$4,Rules!$G$3,Q19=$AD$5,Rules!$G$4,Q19=$AD$6,Rules!$G$5,Q19=$AD$7,Rules!$G$6,Q19=$AD$8,Rules!$G$7,Q19="",) | R22: =IFS(R19=$AD$4,Rules!$G$3,R19=$AD$5,Rules!$G$4,R19=$AD$6,Rules!$G$5,R19=$AD$7,Rules!$G$6,R19=$AD$8,Rules!$G$7,R19="",) | S22: =IFS(S19=$AD$4,Rules!$G$3,S19=$AD$5,Rules!$G$4,S19=$AD$6,Rules!$G$5,S19=$AD$7,Rules!$G$6,S19=$AD$8,Rules!$G$7,S19="",) | T22: =IFS(T19=$AD$4,Rules!$G$3,T19=$AD$5,Rules!$G$4,T19=$AD$6,Rules!$G$5,T19=$AD$7,Rules!$G$6,T19=$AD$8,Rules!$G$7,T19="",) -> 1 | U22: =IFS(U19=$AD$4,Rules!$G$3,U19=$AD$5,Rules!$G$4,U19=$AD$6,Rules!$G$5,U19=$AD$7,Rules!$G$6,U19=$AD$8,Rules!$G$7,U19="",)
B23: =AE3 -> Trey | C23: =IFS(C20=$AD$4,Rules!$G$3,C20=$AD$5,Rules!$G$4,C20=$AD$6,Rules!$G$5,C20=$AD$7,Rules!$G$6,C20=$AD$8,Rules!$G$7,C20="",) | D23: =IFS(D20=$AD$4,Rules!$G$3,D20=$AD$5,Rules!$G$4,D20=$AD$6,Rules!$G$5,D20=$AD$7,Rules!$G$6,D20=$AD$8,Rules!$G$7,D20="",) | E23: =IFS(E20=$AD$4,Rules!$G$3,E20=$AD$5,Rules!$G$4,E20=$AD$6,Rules!$G$5,E20=$AD$7,Rules!$G$6,E20=$AD$8,Rules!$G$7,E20="",) | F23: =IFS(F20=$AD$4,Rules!$G$3,F20=$AD$5,Rules!$G$4,F20=$AD$6,Rules!$G$5,F20=$AD$7,Rules!$G$6,F20=$AD$8,Rules!$G$7,F20="",) | G23: =IFS(G20=$AD$4,Rules!$G$3,G20=$AD$5,Rules!$G$4,G20=$AD$6,Rules!$G$5,G20=$AD$7,Rules!$G$6,G20=$AD$8,Rules!$G$7,G20="",) | H23: =IFS(H20=$AD$4,Rules!$G$3,H20=$AD$5,Rules!$G$4,H20=$AD$6,Rules!$G$5,H20=$AD$7,Rules!$G$6,H20=$AD$8,Rules!$G$7,H20="",) | I23: =IFS(I20=$AD$4,Rules!$G$3,I20=$AD$5,Rules!$G$4,I20=$AD$6,Rules!$G$5,I20=$AD$7,Rules!$G$6,I20=$AD$8,Rules!$G$7,I20="",) -> 1 | J23: =IFS(J20=$AD$4,Rules!$G$3,J20=$AD$5,Rules!$G$4,J20=$AD$6,Rules!$G$5,J20=$AD$7,Rules!$G$6,J20=$AD$8,Rules!$G$7,J20="",) | K23: =IFS(K20=$AD$4,Rules!$G$3,K20=$AD$5,Rules!$G$4,K20=$AD$6,Rules!$G$5,K20=$AD$7,Rules!$G$6,K20=$AD$8,Rules!$G$7,K20="",) | M23: =IFS(M20=$AD$4,Rules!$G$3,M20=$AD$5,Rules!$G$4,M20=$AD$6,Rules!$G$5,M20=$AD$7,Rules!$G$6,M20=$AD$8,Rules!$G$7,M20="",) | N23: =IFS(N20=$AD$4,Rules!$G$3,N20=$AD$5,Rules!$G$4,N20=$AD$6,Rules!$G$5,N20=$AD$7,Rules!$G$6,N20=$AD$8,Rules!$G$7,N20="",) | O23: =IFS(O20=$AD$4,Rules!$G$3,O20=$AD$5,Rules!$G$4,O20=$AD$6,Rules!$G$5,O20=$AD$7,Rules!$G$6,O20=$AD$8,Rules!$G$7,O20="",) | P23: =IFS(P20=$AD$4,Rules!$G$3,P20=$AD$5,Rules!$G$4,P20=$AD$6,Rules!$G$5,P20=$AD$7,Rules!$G$6,P20=$AD$8,Rules!$G$7,P20="",) | Q23: =IFS(Q20=$AD$4,Rules!$G$3,Q20=$AD$5,Rules!$G$4,Q20=$AD$6,Rules!$G$5,Q20=$AD$7,Rules!$G$6,Q20=$AD$8,Rules!$G$7,Q20="",) | R23: =IFS(R20=$AD$4,Rules!$G$3,R20=$AD$5,Rules!$G$4,R20=$AD$6,Rules!$G$5,R20=$AD$7,Rules!$G$6,R20=$AD$8,Rules!$G$7,R20="",) | S23: =IFS(S20=$AD$4,Rules!$G$3,S20=$AD$5,Rules!$G$4,S20=$AD$6,Rules!$G$5,S20=$AD$7,Rules!$G$6,S20=$AD$8,Rules!$G$7,S20="",) -> 1 | T23: =IFS(T20=$AD$4,Rules!$G$3,T20=$AD$5,Rules!$G$4,T20=$AD$6,Rules!$G$5,T20=$AD$7,Rules!$G$6,T20=$AD$8,Rules!$G$7,T20="",) | U23: =IFS(U20=$AD$4,Rules!$G$3,U20=$AD$5,Rules!$G$4,U20=$AD$6,Rules!$G$5,U20=$AD$7,Rules!$G$6,U20=$AD$8,Rules!$G$7,U20="",)
B24: Trent Running Points Won | C24: =C22 -> 1 | D24: =D22+C24 -> 1 | E24: =E22+D24 -> 1 | F24: =F22+E24 -> 2 | G24: =G22+F24 -> 3 | H24: =H22+G24 -> 4 | I24: =I22+H24 -> 4 | J24: =J22+I24 -> 4 | K24: =K22+J24 -> 6 | ... U24: =U22+T24 -> 10
B25: Trey Running Points Won | C25: =C23 | D25: =D23+C25 -> 0 | E25: =E23+D25 -> 0 | F25: =F23+E25 -> 0 | G25: =G23+F25 -> 0 | H25: =H23+G25 -> 0 | I25: =I23+H25 -> 1 | J25: =J23+I25 -> 1 | K25: =K23+J25 -> 1 | ... U25: =U23+T25 -> 2

Sheet Rio Pinar GC - 2026-05-10
B2: Rio Pinar GC | C2: SCORECARD | AB2: Match Stats
B3: 46152 | C3: 1 | D3: 2 | E3: 3 | F3: 4 | G3: 5 | H3: 6 | I3: 7 | J3: 8 | K3: 9 | L3: Front 9 | M3: 10 | N3: 11 | O3: 12 | P3: 13 | Q3: 14 | R3: 15 | S3: 16 | T3: 17 | U3: 18 | V3: Back 9 | W3: PAR | Z3: To Par | AC3: =Rules!I3 -> Trent | AD3: 3 | AE3: =Rules!J3 -> Trey
B4: Par | C4: 5 | D4: 4 | E4: 3 | F4: 4 | G4: 4 | H4: 5 | I4: 3 | J4: 4 | K4: 4 | L4: =SUM(C4:K4) -> 36 | M4: 5 | N4: 4 | O4: 4 | P4: 3 | Q4: 4 | R4: 4 | S4: 5 | T4: 3 | U4: 4 | V4: =SUM(M4:U4) -> 36 | W4: =SUM(L4+V4) -> 72 | AB4: Eagles | AC4: =COUNTIF($C$6:$U$6,"🦅") -> 0 | AD4: 🦅 | AE4: =COUNTIF($C$8:$U$8,"🦅") -> 0
B5: =AC3 -> Trent | C5: 5 | D5: 4 | E5: 3 | F5: 4 | G5: 6 | H5: 6 | I5: 4 | J5: 5 | K5: 6 | L5: =SUM(C5:K5) -> 43 | M5: 5 | N5: 6 | O5: 4 | P5: 3 | Q5: 5 | R5: 6 | S5: 6 | T5: 3 | U5: 6 | V5: =SUM(M5:U5) -> 44 | W5: =SUM(L5+V5) -> 87 | X5: =IFS(W5>$W$4,"+",$W$4>W5,"") -> + | Y5: =W5-$W$4 -> 15 | Z5: =X5&Y5 -> +15 | AB5: Birdies | AC5: =COUNTIF($C$6:$U$6,"🐥") -> 0 | AD5: 🐥 | AE5: =COUNTIF($C$8:$U$8,"🐥") -> 0
C6: =IFS(C$4-C5=1,$AD$5,C$4-C5=2,$AD$4,C$4=C5,$AD$6,C$4-C5=-1,$AD$7,C$4-C5=-2,$AD$8,C$4-C5=-3,$AD$9) -> 🚩 | D6: =IFS(D$4-D5=1,$AD$5,D$4-D5=2,$AD$4,D$4=D5,$AD$6,D$4-D5=-1,$AD$7,D$4-D5=-2,$AD$8,D$4-D5=-3,$AD$9) -> 🚩 | E6: =IFS(E$4-E5=1,$AD$5,E$4-E5=2,$AD$4,E$4=E5,$AD$6,E$4-E5=-1,$AD$7,E$4-E5=-2,$AD$8,E$4-E5=-3,$AD$9) -> 🚩 | F6: =IFS(F$4-F5=1,$AD$5,F$4-F5=2,$AD$4,F$4=F5,$AD$6,F$4-F5=-1,$AD$7,F$4-F5=-2,$AD$8,F$4-F5=-3,$AD$9) -> 🚩 | G6: =IFS(G$4-G5=1,$AD$5,G$4-G5=2,$AD$4,G$4=G5,$AD$6,G$4-G5=-1,$AD$7,G$4-G5=-2,$AD$8,G$4-G5=-3,$AD$9) -> 💩 | H6: =IFS(H$4-H5=1,$AD$5,H$4-H5=2,$AD$4,H$4=H5,$AD$6,H$4-H5=-1,$AD$7,H$4-H5=-2,$AD$8,H$4-H5=-3,$AD$9) -> 🧻 | I6: =IFS(I$4-I5=1,$AD$5,I$4-I5=2,$AD$4,I$4=I5,$AD$6,I$4-I5=-1,$AD$7,I$4-I5=-2,$AD$8,I$4-I5=-3,$AD$9) -> 🧻 | J6: =IFS(J$4-J5=1,$AD$5,J$4-J5=2,$AD$4,J$4=J5,$AD$6,J$4-J5=-1,$AD$7,J$4-J5=-2,$AD$8,J$4-J5=-3,$AD$9) -> 🧻 | K6: =IFS(K$4-K5=1,$AD$5,K$4-K5=2,$AD$4,K$4=K5,$AD$6,K$4-K5=-1,$AD$7,K$4-K5=-2,$AD$8,K$4-K5=-3,$AD$9) -> 💩 | M6: =IFS(M$4-M5=1,$AD$5,M$4-M5=2,$AD$4,M$4=M5,$AD$6,M$4-M5=-1,$AD$7,M$4-M5=-2,$AD$8,M$4-M5=-3,$AD$9) -> 🚩 | N6: =IFS(N$4-N5=1,$AD$5,N$4-N5=2,$AD$4,N$4=N5,$AD$6,N$4-N5=-1,$AD$7,N$4-N5=-2,$AD$8,N$4-N5=-3,$AD$9) -> 💩 | O6: =IFS(O$4-O5=1,$AD$5,O$4-O5=2,$AD$4,O$4=O5,$AD$6,O$4-O5=-1,$AD$7,O$4-O5=-2,$AD$8,O$4-O5=-3,$AD$9) -> 🚩 | P6: =IFS(P$4-P5=1,$AD$5,P$4-P5=2,$AD$4,P$4=P5,$AD$6,P$4-P5=-1,$AD$7,P$4-P5=-2,$AD$8,P$4-P5=-3,$AD$9) -> 🚩 | Q6: =IFS(Q$4-Q5=1,$AD$5,Q$4-Q5=2,$AD$4,Q$4=Q5,$AD$6,Q$4-Q5=-1,$AD$7,Q$4-Q5=-2,$AD$8,Q$4-Q5=-3,$AD$9) -> 🧻 | R6: =IFS(R$4-R5=1,$AD$5,R$4-R5=2,$AD$4,R$4=R5,$AD$6,R$4-R5=-1,$AD$7,R$4-R5=-2,$AD$8,R$4-R5=-3,$AD$9) -> 💩 | S6: =IFS(S$4-S5=1,$AD$5,S$4-S5=2,$AD$4,S$4=S5,$AD$6,S$4-S5=-1,$AD$7,S$4-S5=-2,$AD$8,S$4-S5=-3,$AD$9) -> 🧻 | T6: =IFS(T$4-T5=1,$AD$5,T$4-T5=2,$AD$4,T$4=T5,$AD$6,T$4-T5=-1,$AD$7,T$4-T5=-2,$AD$8,T$4-T5=-3,$AD$9) -> 🚩 | U6: =IFS(U$4-U5=1,$AD$5,U$4-U5=2,$AD$4,U$4=U5,$AD$6,U$4-U5=-1,$AD$7,U$4-U5=-2,$AD$8,U$4-U5=-3,$AD$9) -> 💩 | AB6: Pars | AC6: =COUNTIF($C$6:$U$6,"🚩") -> 8 | AD6: 🚩 | AE6: =COUNTIF($C$8:$U$8,"🚩") -> 6
